[2025-05-06T03:06:45.169+0000] {local_task_job_runner.py:123} INFO - ::group::Pre task execution logs
[2025-05-06T03:06:45.194+0000] {taskinstance.py:2612} INFO - Dependencies all met for dep_context=non-requeueable deps ti=<TaskInstance: BuildELT_dbt.dbt_run manual__2025-05-06T03:06:44.245395+00:00 [queued]>
[2025-05-06T03:06:45.210+0000] {taskinstance.py:2612} INFO - Dependencies all met for dep_context=requeueable deps ti=<TaskInstance: BuildELT_dbt.dbt_run manual__2025-05-06T03:06:44.245395+00:00 [queued]>
[2025-05-06T03:06:45.212+0000] {taskinstance.py:2865} INFO - Starting attempt 1 of 1
[2025-05-06T03:06:45.230+0000] {taskinstance.py:2888} INFO - Executing <Task(BashOperator): dbt_run> on 2025-05-06 03:06:44.245395+00:00
[2025-05-06T03:06:45.240+0000] {standard_task_runner.py:72} INFO - Started process 1636 to run task
[2025-05-06T03:06:45.244+0000] {standard_task_runner.py:104} INFO - Running: ['***', 'tasks', 'run', 'BuildELT_dbt', 'dbt_run', 'manual__2025-05-06T03:06:44.245395+00:00', '--job-id', '31', '--raw', '--subdir', 'DAGS_FOLDER/build_elt_with_dbt.py', '--cfg-path', '/tmp/tmp8rp6u3ey']
[2025-05-06T03:06:45.247+0000] {standard_task_runner.py:105} INFO - Job 31: Subtask dbt_run
[2025-05-06T03:06:45.297+0000] {task_command.py:467} INFO - Running <TaskInstance: BuildELT_dbt.dbt_run manual__2025-05-06T03:06:44.245395+00:00 [running]> on host 4bf74f6ca137
[2025-05-06T03:06:45.393+0000] {taskinstance.py:3131} INFO - Exporting env vars: AIRFLOW_CTX_DAG_OWNER='***' AIRFLOW_CTX_DAG_ID='BuildELT_dbt' AIRFLOW_CTX_TASK_ID='dbt_run' AIRFLOW_CTX_EXECUTION_DATE='2025-05-06T03:06:44.245395+00:00' AIRFLOW_CTX_TRY_NUMBER='1' AIRFLOW_CTX_DAG_RUN_ID='manual__2025-05-06T03:06:44.245395+00:00'
[2025-05-06T03:06:45.395+0000] {taskinstance.py:731} INFO - ::endgroup::
[2025-05-06T03:06:45.413+0000] {subprocess.py:63} INFO - Tmp dir root location: /tmp
[2025-05-06T03:06:45.416+0000] {subprocess.py:75} INFO - Running command: ['/usr/bin/bash', '-c', '/home/***/.local/bin/dbt run --profiles-dir /opt/***/tesla_project --project-dir /opt/***/tesla_project']
[2025-05-06T03:06:45.435+0000] {subprocess.py:86} INFO - Output:
[2025-05-06T03:06:47.513+0000] {subprocess.py:93} INFO - [0m03:06:47  Running with dbt=1.8.7
[2025-05-06T03:06:48.450+0000] {subprocess.py:93} INFO - [0m03:06:48  Registered adapter: snowflake=1.8.1
[2025-05-06T03:06:48.595+0000] {subprocess.py:93} INFO - [0m03:06:48  Unable to do partial parsing because saved manifest not found. Starting full parse.
[2025-05-06T03:06:50.349+0000] {subprocess.py:93} INFO - [0m03:06:50  [[33mWARNING[0m]: Configuration paths exist in your dbt_project.yml file which do not apply to any resources.
[2025-05-06T03:06:50.349+0000] {subprocess.py:93} INFO - There are 1 unused configuration paths:
[2025-05-06T03:06:50.350+0000] {subprocess.py:93} INFO - - models.tesla_project.example
[2025-05-06T03:06:50.549+0000] {subprocess.py:93} INFO - [0m03:06:50  Found 3 models, 1 snapshot, 1 source, 459 macros
[2025-05-06T03:06:50.552+0000] {subprocess.py:93} INFO - [0m03:06:50
[2025-05-06T03:06:54.295+0000] {subprocess.py:93} INFO - [0m03:06:54  Concurrency: 1 threads (target='dev')
[2025-05-06T03:06:54.298+0000] {subprocess.py:93} INFO - [0m03:06:54
[2025-05-06T03:06:54.318+0000] {subprocess.py:93} INFO - [0m03:06:54  1 of 3 START sql table model analytics.input ................................... [RUN]
[2025-05-06T03:06:55.336+0000] {subprocess.py:93} INFO - [0m03:06:55  1 of 3 ERROR creating sql table model analytics.input .......................... [[31mERROR[0m in 1.01s]
[2025-05-06T03:06:55.342+0000] {subprocess.py:93} INFO - [0m03:06:55  2 of 3 SKIP relation analytics.sentiment_features_final ........................ [[33mSKIP[0m]
[2025-05-06T03:06:55.345+0000] {subprocess.py:93} INFO - [0m03:06:55  3 of 3 SKIP relation analytics.output .......................................... [[33mSKIP[0m]
[2025-05-06T03:06:55.351+0000] {subprocess.py:93} INFO - [0m03:06:55
[2025-05-06T03:06:55.352+0000] {subprocess.py:93} INFO - [0m03:06:55  Finished running 3 table models in 0 hours 0 minutes and 4.80 seconds (4.80s).
[2025-05-06T03:06:55.411+0000] {subprocess.py:93} INFO - [0m03:06:55
[2025-05-06T03:06:55.412+0000] {subprocess.py:93} INFO - [0m03:06:55  [31mCompleted with 1 error and 0 warnings:[0m
[2025-05-06T03:06:55.413+0000] {subprocess.py:93} INFO - [0m03:06:55
[2025-05-06T03:06:55.414+0000] {subprocess.py:93} INFO - [0m03:06:55    Database Error in model input (models/input/input.sql)
[2025-05-06T03:06:55.415+0000] {subprocess.py:93} INFO -   002003 (42S02): SQL compilation error:
[2025-05-06T03:06:55.415+0000] {subprocess.py:93} INFO -   Object 'DEV.RAW.FINAL_RAW_MERGED_TABLE' does not exist or not authorized.
[2025-05-06T03:06:55.416+0000] {subprocess.py:93} INFO -   compiled code at target/run/tesla_project/models/input/input.sql
[2025-05-06T03:06:55.416+0000] {subprocess.py:93} INFO - [0m03:06:55
[2025-05-06T03:06:55.417+0000] {subprocess.py:93} INFO - [0m03:06:55  Done. PASS=0 WARN=0 ERROR=1 SKIP=2 TOTAL=3
[2025-05-06T03:06:56.122+0000] {subprocess.py:97} INFO - Command exited with return code 1
[2025-05-06T03:06:56.135+0000] {taskinstance.py:3310} ERROR - Task failed with exception
Traceback (most recent call last):
  File "/home/airflow/.local/lib/python3.9/site-packages/airflow/models/taskinstance.py", line 767, in _execute_task
    result = _execute_callable(context=context, **execute_callable_kwargs)
  File "/home/airflow/.local/lib/python3.9/site-packages/airflow/models/taskinstance.py", line 733, in _execute_callable
    return ExecutionCallableRunner(
  File "/home/airflow/.local/lib/python3.9/site-packages/airflow/utils/operator_helpers.py", line 252, in run
    return self.func(*args, **kwargs)
  File "/home/airflow/.local/lib/python3.9/site-packages/airflow/models/baseoperator.py", line 406, in wrapper
    return func(self, *args, **kwargs)
  File "/home/airflow/.local/lib/python3.9/site-packages/airflow/operators/bash.py", line 249, in execute
    raise AirflowException(
airflow.exceptions.AirflowException: Bash command failed. The command returned a non-zero exit code 1.
[2025-05-06T03:06:56.141+0000] {taskinstance.py:1225} INFO - Marking task as FAILED. dag_id=BuildELT_dbt, task_id=dbt_run, run_id=manual__2025-05-06T03:06:44.245395+00:00, execution_date=20250506T030644, start_date=20250506T030645, end_date=20250506T030656
[2025-05-06T03:06:56.157+0000] {taskinstance.py:340} INFO - ::group::Post task execution logs
[2025-05-06T03:06:56.158+0000] {standard_task_runner.py:124} ERROR - Failed to execute job 31 for task dbt_run (Bash command failed. The command returned a non-zero exit code 1.; 1636)
Traceback (most recent call last):
  File "/home/airflow/.local/lib/python3.9/site-packages/airflow/task/task_runner/standard_task_runner.py", line 117, in _start_by_fork
    ret = args.func(args, dag=self.dag)
  File "/home/airflow/.local/lib/python3.9/site-packages/airflow/cli/cli_config.py", line 49, in command
    return func(*args, **kwargs)
  File "/home/airflow/.local/lib/python3.9/site-packages/airflow/utils/cli.py", line 115, in wrapper
    return f(*args, **kwargs)
  File "/home/airflow/.local/lib/python3.9/site-packages/airflow/cli/commands/task_command.py", line 483, in task_run
    task_return_code = _run_task_by_selected_method(args, _dag, ti)
  File "/home/airflow/.local/lib/python3.9/site-packages/airflow/cli/commands/task_command.py", line 256, in _run_task_by_selected_method
    return _run_raw_task(args, ti)
  File "/home/airflow/.local/lib/python3.9/site-packages/airflow/cli/commands/task_command.py", line 341, in _run_raw_task
    return ti._run_raw_task(
  File "/home/airflow/.local/lib/python3.9/site-packages/airflow/utils/session.py", line 97, in wrapper
    return func(*args, session=session, **kwargs)
  File "/home/airflow/.local/lib/python3.9/site-packages/airflow/models/taskinstance.py", line 3004, in _run_raw_task
    return _run_raw_task(
  File "/home/airflow/.local/lib/python3.9/site-packages/airflow/models/taskinstance.py", line 273, in _run_raw_task
    TaskInstance._execute_task_with_callbacks(
  File "/home/airflow/.local/lib/python3.9/site-packages/airflow/models/taskinstance.py", line 3158, in _execute_task_with_callbacks
    result = self._execute_task(context, task_orig)
  File "/home/airflow/.local/lib/python3.9/site-packages/airflow/models/taskinstance.py", line 3182, in _execute_task
    return _execute_task(self, context, task_orig)
  File "/home/airflow/.local/lib/python3.9/site-packages/airflow/models/taskinstance.py", line 767, in _execute_task
    result = _execute_callable(context=context, **execute_callable_kwargs)
  File "/home/airflow/.local/lib/python3.9/site-packages/airflow/models/taskinstance.py", line 733, in _execute_callable
    return ExecutionCallableRunner(
  File "/home/airflow/.local/lib/python3.9/site-packages/airflow/utils/operator_helpers.py", line 252, in run
    return self.func(*args, **kwargs)
  File "/home/airflow/.local/lib/python3.9/site-packages/airflow/models/baseoperator.py", line 406, in wrapper
    return func(self, *args, **kwargs)
  File "/home/airflow/.local/lib/python3.9/site-packages/airflow/operators/bash.py", line 249, in execute
    raise AirflowException(
airflow.exceptions.AirflowException: Bash command failed. The command returned a non-zero exit code 1.
[2025-05-06T03:06:56.167+0000] {local_task_job_runner.py:266} INFO - Task exited with return code 1
[2025-05-06T03:06:56.190+0000] {taskinstance.py:3900} INFO - 0 downstream tasks scheduled from follow-on schedule check
[2025-05-06T03:06:56.196+0000] {local_task_job_runner.py:245} INFO - ::endgroup::
