[2025-05-07T02:31:01.086+0000] {local_task_job_runner.py:123} INFO - ::group::Pre task execution logs
[2025-05-07T02:31:01.108+0000] {taskinstance.py:2612} INFO - Dependencies all met for dep_context=non-requeueable deps ti=<TaskInstance: BuildELT_dbt.dbt_run manual__2025-05-07T02:30:59.600472+00:00 [queued]>
[2025-05-07T02:31:01.121+0000] {taskinstance.py:2612} INFO - Dependencies all met for dep_context=requeueable deps ti=<TaskInstance: BuildELT_dbt.dbt_run manual__2025-05-07T02:30:59.600472+00:00 [queued]>
[2025-05-07T02:31:01.123+0000] {taskinstance.py:2865} INFO - Starting attempt 1 of 1
[2025-05-07T02:31:01.141+0000] {taskinstance.py:2888} INFO - Executing <Task(BashOperator): dbt_run> on 2025-05-07 02:30:59.600472+00:00
[2025-05-07T02:31:01.152+0000] {standard_task_runner.py:72} INFO - Started process 4574 to run task
[2025-05-07T02:31:01.157+0000] {standard_task_runner.py:104} INFO - Running: ['***', 'tasks', 'run', 'BuildELT_dbt', 'dbt_run', 'manual__2025-05-07T02:30:59.600472+00:00', '--job-id', '55', '--raw', '--subdir', 'DAGS_FOLDER/build_elt_with_dbt.py', '--cfg-path', '/tmp/tmpstrtgru1']
[2025-05-07T02:31:01.162+0000] {standard_task_runner.py:105} INFO - Job 55: Subtask dbt_run
[2025-05-07T02:31:01.225+0000] {task_command.py:467} INFO - Running <TaskInstance: BuildELT_dbt.dbt_run manual__2025-05-07T02:30:59.600472+00:00 [running]> on host 55fd2231a72d
[2025-05-07T02:31:01.324+0000] {taskinstance.py:3131} INFO - Exporting env vars: AIRFLOW_CTX_DAG_OWNER='***' AIRFLOW_CTX_DAG_ID='BuildELT_dbt' AIRFLOW_CTX_TASK_ID='dbt_run' AIRFLOW_CTX_EXECUTION_DATE='2025-05-07T02:30:59.600472+00:00' AIRFLOW_CTX_TRY_NUMBER='1' AIRFLOW_CTX_DAG_RUN_ID='manual__2025-05-07T02:30:59.600472+00:00'
[2025-05-07T02:31:01.325+0000] {taskinstance.py:731} INFO - ::endgroup::
[2025-05-07T02:31:01.347+0000] {subprocess.py:63} INFO - Tmp dir root location: /tmp
[2025-05-07T02:31:01.350+0000] {subprocess.py:75} INFO - Running command: ['/usr/bin/bash', '-c', '/home/***/.local/bin/dbt run --profiles-dir /opt/***/tesla_project --project-dir /opt/***/tesla_project']
[2025-05-07T02:31:01.363+0000] {subprocess.py:86} INFO - Output:
[2025-05-07T02:31:07.532+0000] {subprocess.py:93} INFO - [0m02:31:07  Running with dbt=1.8.7
[2025-05-07T02:31:11.128+0000] {subprocess.py:93} INFO - [0m02:31:11  Registered adapter: snowflake=1.8.1
[2025-05-07T02:31:12.597+0000] {subprocess.py:93} INFO - [0m02:31:12  [[33mWARNING[0m]: Configuration paths exist in your dbt_project.yml file which do not apply to any resources.
[2025-05-07T02:31:12.598+0000] {subprocess.py:93} INFO - There are 1 unused configuration paths:
[2025-05-07T02:31:12.599+0000] {subprocess.py:93} INFO - - models.tesla_project.example
[2025-05-07T02:31:13.001+0000] {subprocess.py:93} INFO - [0m02:31:13  Found 3 models, 1 snapshot, 1 seed, 1 source, 459 macros
[2025-05-07T02:31:13.008+0000] {subprocess.py:93} INFO - [0m02:31:13
[2025-05-07T02:31:16.987+0000] {subprocess.py:93} INFO - [0m02:31:16  Concurrency: 1 threads (target='dev')
[2025-05-07T02:31:16.990+0000] {subprocess.py:93} INFO - [0m02:31:16
[2025-05-07T02:31:17.009+0000] {subprocess.py:93} INFO - [0m02:31:17  1 of 3 START sql table model analytics.input ................................... [RUN]
[2025-05-07T02:31:18.742+0000] {subprocess.py:93} INFO - [0m02:31:18  1 of 3 OK created sql table model analytics.input .............................. [[32mSUCCESS 1[0m in 1.66s]
[2025-05-07T02:31:18.751+0000] {subprocess.py:93} INFO - [0m02:31:18  2 of 3 START sql table model analytics.sentiment_features_final ................ [RUN]
[2025-05-07T02:31:20.834+0000] {subprocess.py:93} INFO - [0m02:31:20  2 of 3 OK created sql table model analytics.sentiment_features_final ........... [[32mSUCCESS 1[0m in 2.08s]
[2025-05-07T02:31:20.842+0000] {subprocess.py:93} INFO - [0m02:31:20  3 of 3 START sql table model analytics.output .................................. [RUN]
[2025-05-07T02:31:22.723+0000] {subprocess.py:93} INFO - [0m02:31:22  3 of 3 ERROR creating sql table model analytics.output ......................... [[31mERROR[0m in 1.87s]
[2025-05-07T02:31:22.742+0000] {subprocess.py:93} INFO - [0m02:31:22
[2025-05-07T02:31:22.745+0000] {subprocess.py:93} INFO - [0m02:31:22  Finished running 3 table models in 0 hours 0 minutes and 9.73 seconds (9.73s).
[2025-05-07T02:31:22.849+0000] {subprocess.py:93} INFO - [0m02:31:22
[2025-05-07T02:31:22.850+0000] {subprocess.py:93} INFO - [0m02:31:22  [31mCompleted with 1 error and 0 warnings:[0m
[2025-05-07T02:31:22.851+0000] {subprocess.py:93} INFO - [0m02:31:22
[2025-05-07T02:31:22.855+0000] {subprocess.py:93} INFO - [0m02:31:22    Database Error in model output (models/output/output.sql)
[2025-05-07T02:31:22.857+0000] {subprocess.py:93} INFO -   000904 (42000): SQL compilation error: error line 8 at position 8
[2025-05-07T02:31:22.859+0000] {subprocess.py:93} INFO -   invalid identifier 'CLOSE'
[2025-05-07T02:31:22.859+0000] {subprocess.py:93} INFO -   compiled code at target/run/tesla_project/models/output/output.sql
[2025-05-07T02:31:22.860+0000] {subprocess.py:93} INFO - [0m02:31:22
[2025-05-07T02:31:22.861+0000] {subprocess.py:93} INFO - [0m02:31:22  Done. PASS=2 WARN=0 ERROR=1 SKIP=0 TOTAL=3
[2025-05-07T02:31:24.188+0000] {subprocess.py:97} INFO - Command exited with return code 1
[2025-05-07T02:31:24.282+0000] {taskinstance.py:3310} ERROR - Task failed with exception
Traceback (most recent call last):
  File "/home/airflow/.local/lib/python3.9/site-packages/airflow/models/taskinstance.py", line 767, in _execute_task
    result = _execute_callable(context=context, **execute_callable_kwargs)
  File "/home/airflow/.local/lib/python3.9/site-packages/airflow/models/taskinstance.py", line 733, in _execute_callable
    return ExecutionCallableRunner(
  File "/home/airflow/.local/lib/python3.9/site-packages/airflow/utils/operator_helpers.py", line 252, in run
    return self.func(*args, **kwargs)
  File "/home/airflow/.local/lib/python3.9/site-packages/airflow/models/baseoperator.py", line 406, in wrapper
    return func(self, *args, **kwargs)
  File "/home/airflow/.local/lib/python3.9/site-packages/airflow/operators/bash.py", line 249, in execute
    raise AirflowException(
airflow.exceptions.AirflowException: Bash command failed. The command returned a non-zero exit code 1.
[2025-05-07T02:31:24.295+0000] {taskinstance.py:1225} INFO - Marking task as FAILED. dag_id=BuildELT_dbt, task_id=dbt_run, run_id=manual__2025-05-07T02:30:59.600472+00:00, execution_date=20250507T023059, start_date=20250507T023101, end_date=20250507T023124
[2025-05-07T02:31:24.338+0000] {taskinstance.py:340} INFO - ::group::Post task execution logs
[2025-05-07T02:31:24.342+0000] {standard_task_runner.py:124} ERROR - Failed to execute job 55 for task dbt_run (Bash command failed. The command returned a non-zero exit code 1.; 4574)
Traceback (most recent call last):
  File "/home/airflow/.local/lib/python3.9/site-packages/airflow/task/task_runner/standard_task_runner.py", line 117, in _start_by_fork
    ret = args.func(args, dag=self.dag)
  File "/home/airflow/.local/lib/python3.9/site-packages/airflow/cli/cli_config.py", line 49, in command
    return func(*args, **kwargs)
  File "/home/airflow/.local/lib/python3.9/site-packages/airflow/utils/cli.py", line 115, in wrapper
    return f(*args, **kwargs)
  File "/home/airflow/.local/lib/python3.9/site-packages/airflow/cli/commands/task_command.py", line 483, in task_run
    task_return_code = _run_task_by_selected_method(args, _dag, ti)
  File "/home/airflow/.local/lib/python3.9/site-packages/airflow/cli/commands/task_command.py", line 256, in _run_task_by_selected_method
    return _run_raw_task(args, ti)
  File "/home/airflow/.local/lib/python3.9/site-packages/airflow/cli/commands/task_command.py", line 341, in _run_raw_task
    return ti._run_raw_task(
  File "/home/airflow/.local/lib/python3.9/site-packages/airflow/utils/session.py", line 97, in wrapper
    return func(*args, session=session, **kwargs)
  File "/home/airflow/.local/lib/python3.9/site-packages/airflow/models/taskinstance.py", line 3004, in _run_raw_task
    return _run_raw_task(
  File "/home/airflow/.local/lib/python3.9/site-packages/airflow/models/taskinstance.py", line 273, in _run_raw_task
    TaskInstance._execute_task_with_callbacks(
  File "/home/airflow/.local/lib/python3.9/site-packages/airflow/models/taskinstance.py", line 3158, in _execute_task_with_callbacks
    result = self._execute_task(context, task_orig)
  File "/home/airflow/.local/lib/python3.9/site-packages/airflow/models/taskinstance.py", line 3182, in _execute_task
    return _execute_task(self, context, task_orig)
  File "/home/airflow/.local/lib/python3.9/site-packages/airflow/models/taskinstance.py", line 767, in _execute_task
    result = _execute_callable(context=context, **execute_callable_kwargs)
  File "/home/airflow/.local/lib/python3.9/site-packages/airflow/models/taskinstance.py", line 733, in _execute_callable
    return ExecutionCallableRunner(
  File "/home/airflow/.local/lib/python3.9/site-packages/airflow/utils/operator_helpers.py", line 252, in run
    return self.func(*args, **kwargs)
  File "/home/airflow/.local/lib/python3.9/site-packages/airflow/models/baseoperator.py", line 406, in wrapper
    return func(self, *args, **kwargs)
  File "/home/airflow/.local/lib/python3.9/site-packages/airflow/operators/bash.py", line 249, in execute
    raise AirflowException(
airflow.exceptions.AirflowException: Bash command failed. The command returned a non-zero exit code 1.
[2025-05-07T02:31:24.390+0000] {local_task_job_runner.py:266} INFO - Task exited with return code 1
[2025-05-07T02:31:24.416+0000] {local_task_job_runner.py:245} INFO - ::endgroup::
