[2025-05-06T03:56:30.340+0000] {local_task_job_runner.py:123} INFO - ::group::Pre task execution logs
[2025-05-06T03:56:30.364+0000] {taskinstance.py:2612} INFO - Dependencies all met for dep_context=non-requeueable deps ti=<TaskInstance: BuildELT_dbt.dbt_run manual__2025-05-06T03:56:27.725449+00:00 [queued]>
[2025-05-06T03:56:30.377+0000] {taskinstance.py:2612} INFO - Dependencies all met for dep_context=requeueable deps ti=<TaskInstance: BuildELT_dbt.dbt_run manual__2025-05-06T03:56:27.725449+00:00 [queued]>
[2025-05-06T03:56:30.379+0000] {taskinstance.py:2865} INFO - Starting attempt 1 of 1
[2025-05-06T03:56:30.400+0000] {taskinstance.py:2888} INFO - Executing <Task(BashOperator): dbt_run> on 2025-05-06 03:56:27.725449+00:00
[2025-05-06T03:56:30.413+0000] {standard_task_runner.py:72} INFO - Started process 2985 to run task
[2025-05-06T03:56:30.417+0000] {standard_task_runner.py:104} INFO - Running: ['***', 'tasks', 'run', 'BuildELT_dbt', 'dbt_run', 'manual__2025-05-06T03:56:27.725449+00:00', '--job-id', '34', '--raw', '--subdir', 'DAGS_FOLDER/build_elt_with_dbt.py', '--cfg-path', '/tmp/tmp0a8n_5yd']
[2025-05-06T03:56:30.420+0000] {standard_task_runner.py:105} INFO - Job 34: Subtask dbt_run
[2025-05-06T03:56:30.468+0000] {task_command.py:467} INFO - Running <TaskInstance: BuildELT_dbt.dbt_run manual__2025-05-06T03:56:27.725449+00:00 [running]> on host 4bf74f6ca137
[2025-05-06T03:56:30.553+0000] {taskinstance.py:3131} INFO - Exporting env vars: AIRFLOW_CTX_DAG_OWNER='***' AIRFLOW_CTX_DAG_ID='BuildELT_dbt' AIRFLOW_CTX_TASK_ID='dbt_run' AIRFLOW_CTX_EXECUTION_DATE='2025-05-06T03:56:27.725449+00:00' AIRFLOW_CTX_TRY_NUMBER='1' AIRFLOW_CTX_DAG_RUN_ID='manual__2025-05-06T03:56:27.725449+00:00'
[2025-05-06T03:56:30.556+0000] {taskinstance.py:731} INFO - ::endgroup::
[2025-05-06T03:56:30.587+0000] {subprocess.py:63} INFO - Tmp dir root location: /tmp
[2025-05-06T03:56:30.590+0000] {subprocess.py:75} INFO - Running command: ['/usr/bin/bash', '-c', '/home/***/.local/bin/dbt run --profiles-dir /opt/***/tesla_project --project-dir /opt/***/tesla_project']
[2025-05-06T03:56:30.606+0000] {subprocess.py:86} INFO - Output:
[2025-05-06T03:56:33.187+0000] {subprocess.py:93} INFO - [0m03:56:33  Running with dbt=1.8.7
[2025-05-06T03:56:34.702+0000] {subprocess.py:93} INFO - [0m03:56:34  Registered adapter: snowflake=1.8.1
[2025-05-06T03:56:34.998+0000] {subprocess.py:93} INFO - [0m03:56:34  Unable to do partial parsing because a project config has changed
[2025-05-06T03:56:37.076+0000] {subprocess.py:93} INFO - [0m03:56:37  Encountered an error:
[2025-05-06T03:56:37.078+0000] {subprocess.py:93} INFO - Compilation Error
[2025-05-06T03:56:37.079+0000] {subprocess.py:93} INFO -   Snapshot 'snapshot.tesla_project.Final_raw_snapshot' (snapshots/final_raw_snapshot.sql) depends on a source named 'raw.Final_raw_table' which was not found
[2025-05-06T03:56:38.820+0000] {subprocess.py:97} INFO - Command exited with return code 2
[2025-05-06T03:56:38.832+0000] {taskinstance.py:3310} ERROR - Task failed with exception
Traceback (most recent call last):
  File "/home/airflow/.local/lib/python3.9/site-packages/airflow/models/taskinstance.py", line 767, in _execute_task
    result = _execute_callable(context=context, **execute_callable_kwargs)
  File "/home/airflow/.local/lib/python3.9/site-packages/airflow/models/taskinstance.py", line 733, in _execute_callable
    return ExecutionCallableRunner(
  File "/home/airflow/.local/lib/python3.9/site-packages/airflow/utils/operator_helpers.py", line 252, in run
    return self.func(*args, **kwargs)
  File "/home/airflow/.local/lib/python3.9/site-packages/airflow/models/baseoperator.py", line 406, in wrapper
    return func(self, *args, **kwargs)
  File "/home/airflow/.local/lib/python3.9/site-packages/airflow/operators/bash.py", line 249, in execute
    raise AirflowException(
airflow.exceptions.AirflowException: Bash command failed. The command returned a non-zero exit code 2.
[2025-05-06T03:56:38.838+0000] {taskinstance.py:1225} INFO - Marking task as FAILED. dag_id=BuildELT_dbt, task_id=dbt_run, run_id=manual__2025-05-06T03:56:27.725449+00:00, execution_date=20250506T035627, start_date=20250506T035630, end_date=20250506T035638
[2025-05-06T03:56:38.853+0000] {taskinstance.py:340} INFO - ::group::Post task execution logs
[2025-05-06T03:56:38.855+0000] {standard_task_runner.py:124} ERROR - Failed to execute job 34 for task dbt_run (Bash command failed. The command returned a non-zero exit code 2.; 2985)
Traceback (most recent call last):
  File "/home/airflow/.local/lib/python3.9/site-packages/airflow/task/task_runner/standard_task_runner.py", line 117, in _start_by_fork
    ret = args.func(args, dag=self.dag)
  File "/home/airflow/.local/lib/python3.9/site-packages/airflow/cli/cli_config.py", line 49, in command
    return func(*args, **kwargs)
  File "/home/airflow/.local/lib/python3.9/site-packages/airflow/utils/cli.py", line 115, in wrapper
    return f(*args, **kwargs)
  File "/home/airflow/.local/lib/python3.9/site-packages/airflow/cli/commands/task_command.py", line 483, in task_run
    task_return_code = _run_task_by_selected_method(args, _dag, ti)
  File "/home/airflow/.local/lib/python3.9/site-packages/airflow/cli/commands/task_command.py", line 256, in _run_task_by_selected_method
    return _run_raw_task(args, ti)
  File "/home/airflow/.local/lib/python3.9/site-packages/airflow/cli/commands/task_command.py", line 341, in _run_raw_task
    return ti._run_raw_task(
  File "/home/airflow/.local/lib/python3.9/site-packages/airflow/utils/session.py", line 97, in wrapper
    return func(*args, session=session, **kwargs)
  File "/home/airflow/.local/lib/python3.9/site-packages/airflow/models/taskinstance.py", line 3004, in _run_raw_task
    return _run_raw_task(
  File "/home/airflow/.local/lib/python3.9/site-packages/airflow/models/taskinstance.py", line 273, in _run_raw_task
    TaskInstance._execute_task_with_callbacks(
  File "/home/airflow/.local/lib/python3.9/site-packages/airflow/models/taskinstance.py", line 3158, in _execute_task_with_callbacks
    result = self._execute_task(context, task_orig)
  File "/home/airflow/.local/lib/python3.9/site-packages/airflow/models/taskinstance.py", line 3182, in _execute_task
    return _execute_task(self, context, task_orig)
  File "/home/airflow/.local/lib/python3.9/site-packages/airflow/models/taskinstance.py", line 767, in _execute_task
    result = _execute_callable(context=context, **execute_callable_kwargs)
  File "/home/airflow/.local/lib/python3.9/site-packages/airflow/models/taskinstance.py", line 733, in _execute_callable
    return ExecutionCallableRunner(
  File "/home/airflow/.local/lib/python3.9/site-packages/airflow/utils/operator_helpers.py", line 252, in run
    return self.func(*args, **kwargs)
  File "/home/airflow/.local/lib/python3.9/site-packages/airflow/models/baseoperator.py", line 406, in wrapper
    return func(self, *args, **kwargs)
  File "/home/airflow/.local/lib/python3.9/site-packages/airflow/operators/bash.py", line 249, in execute
    raise AirflowException(
airflow.exceptions.AirflowException: Bash command failed. The command returned a non-zero exit code 2.
[2025-05-06T03:56:38.882+0000] {local_task_job_runner.py:266} INFO - Task exited with return code 1
[2025-05-06T03:56:38.901+0000] {taskinstance.py:3900} INFO - 0 downstream tasks scheduled from follow-on schedule check
[2025-05-06T03:56:38.905+0000] {local_task_job_runner.py:245} INFO - ::endgroup::
