[2025-05-04T00:13:07.858+0000] {local_task_job_runner.py:123} INFO - ::group::Pre task execution logs
[2025-05-04T00:13:07.922+0000] {taskinstance.py:2612} INFO - Dependencies all met for dep_context=non-requeueable deps ti=<TaskInstance: tesla_stock_sentiment_final_etl.load_stock_data_to_snowflake manual__2025-05-03T21:31:27.530313+00:00 [queued]>
[2025-05-04T00:13:07.979+0000] {taskinstance.py:2612} INFO - Dependencies all met for dep_context=requeueable deps ti=<TaskInstance: tesla_stock_sentiment_final_etl.load_stock_data_to_snowflake manual__2025-05-03T21:31:27.530313+00:00 [queued]>
[2025-05-04T00:13:07.996+0000] {taskinstance.py:2865} INFO - Starting attempt 1 of 1
[2025-05-04T00:13:08.028+0000] {taskinstance.py:2888} INFO - Executing <Task(_PythonDecoratedOperator): load_stock_data_to_snowflake> on 2025-05-03 21:31:27.530313+00:00
[2025-05-04T00:13:08.045+0000] {standard_task_runner.py:72} INFO - Started process 1208 to run task
[2025-05-04T00:13:08.057+0000] {standard_task_runner.py:104} INFO - Running: ['***', 'tasks', 'run', 'tesla_stock_sentiment_final_etl', 'load_stock_data_to_snowflake', 'manual__2025-05-03T21:31:27.530313+00:00', '--job-id', '90', '--raw', '--subdir', 'DAGS_FOLDER/tesla_stock_etl.py', '--cfg-path', '/tmp/tmp0xxs845l']
[2025-05-04T00:13:08.063+0000] {standard_task_runner.py:105} INFO - Job 90: Subtask load_stock_data_to_snowflake
[2025-05-04T00:13:08.167+0000] {task_command.py:467} INFO - Running <TaskInstance: tesla_stock_sentiment_final_etl.load_stock_data_to_snowflake manual__2025-05-03T21:31:27.530313+00:00 [running]> on host 7f722b744d3e
[2025-05-04T00:13:08.793+0000] {taskinstance.py:3131} INFO - Exporting env vars: AIRFLOW_CTX_DAG_OWNER='***' AIRFLOW_CTX_DAG_ID='tesla_stock_sentiment_final_etl' AIRFLOW_CTX_TASK_ID='load_stock_data_to_snowflake' AIRFLOW_CTX_EXECUTION_DATE='2025-05-03T21:31:27.530313+00:00' AIRFLOW_CTX_TRY_NUMBER='1' AIRFLOW_CTX_DAG_RUN_ID='manual__2025-05-03T21:31:27.530313+00:00'
[2025-05-04T00:13:08.803+0000] {taskinstance.py:731} INFO - ::endgroup::
[2025-05-04T00:13:08.857+0000] {base.py:84} INFO - Retrieving connection 'snowflake_conn'
[2025-05-04T00:13:08.859+0000] {connection.py:413} INFO - Snowflake Connector for Python Version: 3.12.1, Python Version: 3.9.19, Platform: Linux-5.15.167.4-microsoft-standard-WSL2-x86_64-with-glibc2.36
[2025-05-04T00:13:08.861+0000] {connection.py:1196} INFO - Connecting to GLOBAL Snowflake domain
[2025-05-04T00:13:08.863+0000] {connection.py:1277} INFO - This connection is in OCSP Fail Open Mode. TLS Certificates would be checked for validity and revocation status. Any other Certificate Revocation related exceptions or OCSP Responder failures would be disregarded in favor of connectivity.
[2025-05-04T00:19:13.259+0000] {connectionpool.py:824} WARNING - Retrying (Retry(total=0, connect=None, read=None, redirect=None, status=None)) after connection broken by 'ConnectTimeoutError(<snowflake.connector.vendored.urllib3.connection.HTTPSConnection object at 0x7f86a0b7b430>, 'Connection to oweegxt-gvb74384.snowflakecomputing.com timed out. (connect timeout=60)')': /session/v1/login-request?request_id=ca85dae7-431d-421a-b9df-7761deb2b79c&databaseName=dev&schemaName=&warehouse=compute_wh&roleName=&request_guid=984a61f1-9817-42a4-a34b-f37dd448c9d3
[2025-05-04T00:19:17.510+0000] {taskinstance.py:3310} ERROR - Task failed with exception
Traceback (most recent call last):
  File "/home/airflow/.local/lib/python3.9/site-packages/snowflake/connector/vendored/urllib3/connection.py", line 174, in _new_conn
    conn = connection.create_connection(
  File "/home/airflow/.local/lib/python3.9/site-packages/snowflake/connector/vendored/urllib3/util/connection.py", line 79, in create_connection
    for res in socket.getaddrinfo(host, port, family, socket.SOCK_STREAM):
  File "/usr/local/lib/python3.9/socket.py", line 954, in getaddrinfo
    for res in _socket.getaddrinfo(host, port, family, type, proto, flags):
socket.gaierror: [Errno -3] Temporary failure in name resolution

During handling of the above exception, another exception occurred:

Traceback (most recent call last):
  File "/home/airflow/.local/lib/python3.9/site-packages/snowflake/connector/vendored/urllib3/connectionpool.py", line 715, in urlopen
    httplib_response = self._make_request(
  File "/home/airflow/.local/lib/python3.9/site-packages/snowflake/connector/vendored/urllib3/connectionpool.py", line 404, in _make_request
    self._validate_conn(conn)
  File "/home/airflow/.local/lib/python3.9/site-packages/snowflake/connector/vendored/urllib3/connectionpool.py", line 1058, in _validate_conn
    conn.connect()
  File "/home/airflow/.local/lib/python3.9/site-packages/snowflake/connector/vendored/urllib3/connection.py", line 363, in connect
    self.sock = conn = self._new_conn()
  File "/home/airflow/.local/lib/python3.9/site-packages/snowflake/connector/vendored/urllib3/connection.py", line 186, in _new_conn
    raise NewConnectionError(
snowflake.connector.vendored.urllib3.exceptions.NewConnectionError: <snowflake.connector.vendored.urllib3.connection.HTTPSConnection object at 0x7f86a0b7b610>: Failed to establish a new connection: [Errno -3] Temporary failure in name resolution

During handling of the above exception, another exception occurred:

Traceback (most recent call last):
  File "/home/airflow/.local/lib/python3.9/site-packages/snowflake/connector/vendored/requests/adapters.py", line 486, in send
    resp = conn.urlopen(
  File "/home/airflow/.local/lib/python3.9/site-packages/snowflake/connector/vendored/urllib3/connectionpool.py", line 827, in urlopen
    return self.urlopen(
  File "/home/airflow/.local/lib/python3.9/site-packages/snowflake/connector/vendored/urllib3/connectionpool.py", line 799, in urlopen
    retries = retries.increment(
  File "/home/airflow/.local/lib/python3.9/site-packages/snowflake/connector/vendored/urllib3/util/retry.py", line 592, in increment
    raise MaxRetryError(_pool, url, error or ResponseError(cause))
snowflake.connector.vendored.urllib3.exceptions.MaxRetryError: HTTPSConnectionPool(host='oweegxt-gvb74384.snowflakecomputing.com', port=443): Max retries exceeded with url: /session/v1/login-request?request_id=ca85dae7-431d-421a-b9df-7761deb2b79c&databaseName=dev&schemaName=&warehouse=compute_wh&roleName=&request_guid=984a61f1-9817-42a4-a34b-f37dd448c9d3 (Caused by NewConnectionError('<snowflake.connector.vendored.urllib3.connection.HTTPSConnection object at 0x7f86a0b7b610>: Failed to establish a new connection: [Errno -3] Temporary failure in name resolution'))

During handling of the above exception, another exception occurred:

Traceback (most recent call last):
  File "/home/airflow/.local/lib/python3.9/site-packages/snowflake/connector/network.py", line 1059, in _request_exec
    raw_ret = session.request(
  File "/home/airflow/.local/lib/python3.9/site-packages/snowflake/connector/vendored/requests/sessions.py", line 589, in request
    resp = self.send(prep, **send_kwargs)
  File "/home/airflow/.local/lib/python3.9/site-packages/snowflake/connector/vendored/requests/sessions.py", line 703, in send
    r = adapter.send(request, **kwargs)
  File "/home/airflow/.local/lib/python3.9/site-packages/snowflake/connector/vendored/requests/adapters.py", line 519, in send
    raise ConnectionError(e, request=request)
snowflake.connector.vendored.requests.exceptions.ConnectionError: HTTPSConnectionPool(host='oweegxt-gvb74384.snowflakecomputing.com', port=443): Max retries exceeded with url: /session/v1/login-request?request_id=ca85dae7-431d-421a-b9df-7761deb2b79c&databaseName=dev&schemaName=&warehouse=compute_wh&roleName=&request_guid=984a61f1-9817-42a4-a34b-f37dd448c9d3 (Caused by NewConnectionError('<snowflake.connector.vendored.urllib3.connection.HTTPSConnection object at 0x7f86a0b7b610>: Failed to establish a new connection: [Errno -3] Temporary failure in name resolution'))

During handling of the above exception, another exception occurred:

Traceback (most recent call last):
  File "/home/airflow/.local/lib/python3.9/site-packages/snowflake/connector/connection.py", line 1414, in _authenticate
    auth.authenticate(
  File "/home/airflow/.local/lib/python3.9/site-packages/snowflake/connector/auth/_auth.py", line 250, in authenticate
    ret = self._rest._post_request(
  File "/home/airflow/.local/lib/python3.9/site-packages/snowflake/connector/network.py", line 739, in _post_request
    ret = self.fetch(
  File "/home/airflow/.local/lib/python3.9/site-packages/snowflake/connector/network.py", line 854, in fetch
    ret = self._request_exec_wrapper(
  File "/home/airflow/.local/lib/python3.9/site-packages/snowflake/connector/network.py", line 971, in _request_exec_wrapper
    raise e
  File "/home/airflow/.local/lib/python3.9/site-packages/snowflake/connector/network.py", line 896, in _request_exec_wrapper
    return_object = self._request_exec(
  File "/home/airflow/.local/lib/python3.9/site-packages/snowflake/connector/network.py", line 1144, in _request_exec
    raise OperationalError(
snowflake.connector.errors.OperationalError: 251011: 251011: ConnectionTimeout occurred during login. Will be handled by authenticator

The above exception was the direct cause of the following exception:

Traceback (most recent call last):
  File "/home/airflow/.local/lib/python3.9/site-packages/airflow/models/taskinstance.py", line 767, in _execute_task
    result = _execute_callable(context=context, **execute_callable_kwargs)
  File "/home/airflow/.local/lib/python3.9/site-packages/airflow/models/taskinstance.py", line 733, in _execute_callable
    return ExecutionCallableRunner(
  File "/home/airflow/.local/lib/python3.9/site-packages/airflow/utils/operator_helpers.py", line 252, in run
    return self.func(*args, **kwargs)
  File "/home/airflow/.local/lib/python3.9/site-packages/airflow/models/baseoperator.py", line 406, in wrapper
    return func(self, *args, **kwargs)
  File "/home/airflow/.local/lib/python3.9/site-packages/airflow/decorators/base.py", line 266, in execute
    return_value = super().execute(context)
  File "/home/airflow/.local/lib/python3.9/site-packages/airflow/models/baseoperator.py", line 406, in wrapper
    return func(self, *args, **kwargs)
  File "/home/airflow/.local/lib/python3.9/site-packages/airflow/operators/python.py", line 238, in execute
    return_value = self.execute_callable()
  File "/home/airflow/.local/lib/python3.9/site-packages/airflow/operators/python.py", line 256, in execute_callable
    return runner.run(*self.op_args, **self.op_kwargs)
  File "/home/airflow/.local/lib/python3.9/site-packages/airflow/utils/operator_helpers.py", line 252, in run
    return self.func(*args, **kwargs)
  File "/opt/airflow/dags/tesla_stock_etl.py", line 16, in load_stock_data_to_snowflake
    cur = return_snowflake_conn()
  File "/opt/airflow/dags/tesla_stock_etl.py", line 11, in return_snowflake_conn
    conn = hook.get_conn()
  File "/home/airflow/.local/lib/python3.9/site-packages/airflow/providers/snowflake/hooks/snowflake.py", line 300, in get_conn
    conn = connector.connect(**conn_config)
  File "/home/airflow/.local/lib/python3.9/site-packages/snowflake/connector/__init__.py", line 55, in Connect
    return SnowflakeConnection(**kwargs)
  File "/home/airflow/.local/lib/python3.9/site-packages/snowflake/connector/connection.py", line 456, in __init__
    self.connect(**kwargs)
  File "/home/airflow/.local/lib/python3.9/site-packages/snowflake/connector/connection.py", line 771, in connect
    self.__open_connection()
  File "/home/airflow/.local/lib/python3.9/site-packages/snowflake/connector/connection.py", line 1099, in __open_connection
    self.authenticate_with_retry(self.auth_class)
  File "/home/airflow/.local/lib/python3.9/site-packages/snowflake/connector/connection.py", line 1386, in authenticate_with_retry
    self._authenticate(auth_instance)
  File "/home/airflow/.local/lib/python3.9/site-packages/snowflake/connector/connection.py", line 1458, in _authenticate
    raise auth_op from e
  File "/home/airflow/.local/lib/python3.9/site-packages/snowflake/connector/connection.py", line 1435, in _authenticate
    auth_instance.handle_timeout(
  File "/home/airflow/.local/lib/python3.9/site-packages/snowflake/connector/auth/by_plugin.py", line 212, in handle_timeout
    raise error
snowflake.connector.errors.OperationalError: 250001: 250001: Could not connect to Snowflake backend after 1 attempt(s).Aborting
[2025-05-04T00:19:17.690+0000] {taskinstance.py:1225} INFO - Marking task as FAILED. dag_id=tesla_stock_sentiment_final_etl, task_id=load_stock_data_to_snowflake, run_id=manual__2025-05-03T21:31:27.530313+00:00, execution_date=20250503T213127, start_date=20250504T001307, end_date=20250504T001917
[2025-05-04T00:19:17.844+0000] {taskinstance.py:340} INFO - ::group::Post task execution logs
[2025-05-04T00:19:17.849+0000] {standard_task_runner.py:124} ERROR - Failed to execute job 90 for task load_stock_data_to_snowflake (250001: 250001: Could not connect to Snowflake backend after 1 attempt(s).Aborting; 1208)
Traceback (most recent call last):
  File "/home/airflow/.local/lib/python3.9/site-packages/snowflake/connector/vendored/urllib3/connection.py", line 174, in _new_conn
    conn = connection.create_connection(
  File "/home/airflow/.local/lib/python3.9/site-packages/snowflake/connector/vendored/urllib3/util/connection.py", line 79, in create_connection
    for res in socket.getaddrinfo(host, port, family, socket.SOCK_STREAM):
  File "/usr/local/lib/python3.9/socket.py", line 954, in getaddrinfo
    for res in _socket.getaddrinfo(host, port, family, type, proto, flags):
socket.gaierror: [Errno -3] Temporary failure in name resolution

During handling of the above exception, another exception occurred:

Traceback (most recent call last):
  File "/home/airflow/.local/lib/python3.9/site-packages/snowflake/connector/vendored/urllib3/connectionpool.py", line 715, in urlopen
    httplib_response = self._make_request(
  File "/home/airflow/.local/lib/python3.9/site-packages/snowflake/connector/vendored/urllib3/connectionpool.py", line 404, in _make_request
    self._validate_conn(conn)
  File "/home/airflow/.local/lib/python3.9/site-packages/snowflake/connector/vendored/urllib3/connectionpool.py", line 1058, in _validate_conn
    conn.connect()
  File "/home/airflow/.local/lib/python3.9/site-packages/snowflake/connector/vendored/urllib3/connection.py", line 363, in connect
    self.sock = conn = self._new_conn()
  File "/home/airflow/.local/lib/python3.9/site-packages/snowflake/connector/vendored/urllib3/connection.py", line 186, in _new_conn
    raise NewConnectionError(
snowflake.connector.vendored.urllib3.exceptions.NewConnectionError: <snowflake.connector.vendored.urllib3.connection.HTTPSConnection object at 0x7f86a0b7b610>: Failed to establish a new connection: [Errno -3] Temporary failure in name resolution

During handling of the above exception, another exception occurred:

Traceback (most recent call last):
  File "/home/airflow/.local/lib/python3.9/site-packages/snowflake/connector/vendored/requests/adapters.py", line 486, in send
    resp = conn.urlopen(
  File "/home/airflow/.local/lib/python3.9/site-packages/snowflake/connector/vendored/urllib3/connectionpool.py", line 827, in urlopen
    return self.urlopen(
  File "/home/airflow/.local/lib/python3.9/site-packages/snowflake/connector/vendored/urllib3/connectionpool.py", line 799, in urlopen
    retries = retries.increment(
  File "/home/airflow/.local/lib/python3.9/site-packages/snowflake/connector/vendored/urllib3/util/retry.py", line 592, in increment
    raise MaxRetryError(_pool, url, error or ResponseError(cause))
snowflake.connector.vendored.urllib3.exceptions.MaxRetryError: HTTPSConnectionPool(host='oweegxt-gvb74384.snowflakecomputing.com', port=443): Max retries exceeded with url: /session/v1/login-request?request_id=ca85dae7-431d-421a-b9df-7761deb2b79c&databaseName=dev&schemaName=&warehouse=compute_wh&roleName=&request_guid=984a61f1-9817-42a4-a34b-f37dd448c9d3 (Caused by NewConnectionError('<snowflake.connector.vendored.urllib3.connection.HTTPSConnection object at 0x7f86a0b7b610>: Failed to establish a new connection: [Errno -3] Temporary failure in name resolution'))

During handling of the above exception, another exception occurred:

Traceback (most recent call last):
  File "/home/airflow/.local/lib/python3.9/site-packages/snowflake/connector/network.py", line 1059, in _request_exec
    raw_ret = session.request(
  File "/home/airflow/.local/lib/python3.9/site-packages/snowflake/connector/vendored/requests/sessions.py", line 589, in request
    resp = self.send(prep, **send_kwargs)
  File "/home/airflow/.local/lib/python3.9/site-packages/snowflake/connector/vendored/requests/sessions.py", line 703, in send
    r = adapter.send(request, **kwargs)
  File "/home/airflow/.local/lib/python3.9/site-packages/snowflake/connector/vendored/requests/adapters.py", line 519, in send
    raise ConnectionError(e, request=request)
snowflake.connector.vendored.requests.exceptions.ConnectionError: HTTPSConnectionPool(host='oweegxt-gvb74384.snowflakecomputing.com', port=443): Max retries exceeded with url: /session/v1/login-request?request_id=ca85dae7-431d-421a-b9df-7761deb2b79c&databaseName=dev&schemaName=&warehouse=compute_wh&roleName=&request_guid=984a61f1-9817-42a4-a34b-f37dd448c9d3 (Caused by NewConnectionError('<snowflake.connector.vendored.urllib3.connection.HTTPSConnection object at 0x7f86a0b7b610>: Failed to establish a new connection: [Errno -3] Temporary failure in name resolution'))

During handling of the above exception, another exception occurred:

Traceback (most recent call last):
  File "/home/airflow/.local/lib/python3.9/site-packages/snowflake/connector/connection.py", line 1414, in _authenticate
    auth.authenticate(
  File "/home/airflow/.local/lib/python3.9/site-packages/snowflake/connector/auth/_auth.py", line 250, in authenticate
    ret = self._rest._post_request(
  File "/home/airflow/.local/lib/python3.9/site-packages/snowflake/connector/network.py", line 739, in _post_request
    ret = self.fetch(
  File "/home/airflow/.local/lib/python3.9/site-packages/snowflake/connector/network.py", line 854, in fetch
    ret = self._request_exec_wrapper(
  File "/home/airflow/.local/lib/python3.9/site-packages/snowflake/connector/network.py", line 971, in _request_exec_wrapper
    raise e
  File "/home/airflow/.local/lib/python3.9/site-packages/snowflake/connector/network.py", line 896, in _request_exec_wrapper
    return_object = self._request_exec(
  File "/home/airflow/.local/lib/python3.9/site-packages/snowflake/connector/network.py", line 1144, in _request_exec
    raise OperationalError(
snowflake.connector.errors.OperationalError: 251011: 251011: ConnectionTimeout occurred during login. Will be handled by authenticator

The above exception was the direct cause of the following exception:

Traceback (most recent call last):
  File "/home/airflow/.local/lib/python3.9/site-packages/airflow/task/task_runner/standard_task_runner.py", line 117, in _start_by_fork
    ret = args.func(args, dag=self.dag)
  File "/home/airflow/.local/lib/python3.9/site-packages/airflow/cli/cli_config.py", line 49, in command
    return func(*args, **kwargs)
  File "/home/airflow/.local/lib/python3.9/site-packages/airflow/utils/cli.py", line 115, in wrapper
    return f(*args, **kwargs)
  File "/home/airflow/.local/lib/python3.9/site-packages/airflow/cli/commands/task_command.py", line 483, in task_run
    task_return_code = _run_task_by_selected_method(args, _dag, ti)
  File "/home/airflow/.local/lib/python3.9/site-packages/airflow/cli/commands/task_command.py", line 256, in _run_task_by_selected_method
    return _run_raw_task(args, ti)
  File "/home/airflow/.local/lib/python3.9/site-packages/airflow/cli/commands/task_command.py", line 341, in _run_raw_task
    return ti._run_raw_task(
  File "/home/airflow/.local/lib/python3.9/site-packages/airflow/utils/session.py", line 97, in wrapper
    return func(*args, session=session, **kwargs)
  File "/home/airflow/.local/lib/python3.9/site-packages/airflow/models/taskinstance.py", line 3004, in _run_raw_task
    return _run_raw_task(
  File "/home/airflow/.local/lib/python3.9/site-packages/airflow/models/taskinstance.py", line 273, in _run_raw_task
    TaskInstance._execute_task_with_callbacks(
  File "/home/airflow/.local/lib/python3.9/site-packages/airflow/models/taskinstance.py", line 3158, in _execute_task_with_callbacks
    result = self._execute_task(context, task_orig)
  File "/home/airflow/.local/lib/python3.9/site-packages/airflow/models/taskinstance.py", line 3182, in _execute_task
    return _execute_task(self, context, task_orig)
  File "/home/airflow/.local/lib/python3.9/site-packages/airflow/models/taskinstance.py", line 767, in _execute_task
    result = _execute_callable(context=context, **execute_callable_kwargs)
  File "/home/airflow/.local/lib/python3.9/site-packages/airflow/models/taskinstance.py", line 733, in _execute_callable
    return ExecutionCallableRunner(
  File "/home/airflow/.local/lib/python3.9/site-packages/airflow/utils/operator_helpers.py", line 252, in run
    return self.func(*args, **kwargs)
  File "/home/airflow/.local/lib/python3.9/site-packages/airflow/models/baseoperator.py", line 406, in wrapper
    return func(self, *args, **kwargs)
  File "/home/airflow/.local/lib/python3.9/site-packages/airflow/decorators/base.py", line 266, in execute
    return_value = super().execute(context)
  File "/home/airflow/.local/lib/python3.9/site-packages/airflow/models/baseoperator.py", line 406, in wrapper
    return func(self, *args, **kwargs)
  File "/home/airflow/.local/lib/python3.9/site-packages/airflow/operators/python.py", line 238, in execute
    return_value = self.execute_callable()
  File "/home/airflow/.local/lib/python3.9/site-packages/airflow/operators/python.py", line 256, in execute_callable
    return runner.run(*self.op_args, **self.op_kwargs)
  File "/home/airflow/.local/lib/python3.9/site-packages/airflow/utils/operator_helpers.py", line 252, in run
    return self.func(*args, **kwargs)
  File "/opt/airflow/dags/tesla_stock_etl.py", line 16, in load_stock_data_to_snowflake
    cur = return_snowflake_conn()
  File "/opt/airflow/dags/tesla_stock_etl.py", line 11, in return_snowflake_conn
    conn = hook.get_conn()
  File "/home/airflow/.local/lib/python3.9/site-packages/airflow/providers/snowflake/hooks/snowflake.py", line 300, in get_conn
    conn = connector.connect(**conn_config)
  File "/home/airflow/.local/lib/python3.9/site-packages/snowflake/connector/__init__.py", line 55, in Connect
    return SnowflakeConnection(**kwargs)
  File "/home/airflow/.local/lib/python3.9/site-packages/snowflake/connector/connection.py", line 456, in __init__
    self.connect(**kwargs)
  File "/home/airflow/.local/lib/python3.9/site-packages/snowflake/connector/connection.py", line 771, in connect
    self.__open_connection()
  File "/home/airflow/.local/lib/python3.9/site-packages/snowflake/connector/connection.py", line 1099, in __open_connection
    self.authenticate_with_retry(self.auth_class)
  File "/home/airflow/.local/lib/python3.9/site-packages/snowflake/connector/connection.py", line 1386, in authenticate_with_retry
    self._authenticate(auth_instance)
  File "/home/airflow/.local/lib/python3.9/site-packages/snowflake/connector/connection.py", line 1458, in _authenticate
    raise auth_op from e
  File "/home/airflow/.local/lib/python3.9/site-packages/snowflake/connector/connection.py", line 1435, in _authenticate
    auth_instance.handle_timeout(
  File "/home/airflow/.local/lib/python3.9/site-packages/snowflake/connector/auth/by_plugin.py", line 212, in handle_timeout
    raise error
snowflake.connector.errors.OperationalError: 250001: 250001: Could not connect to Snowflake backend after 1 attempt(s).Aborting
[2025-05-04T00:19:17.923+0000] {local_task_job_runner.py:266} INFO - Task exited with return code 1
[2025-05-04T00:19:18.062+0000] {taskinstance.py:3900} INFO - 0 downstream tasks scheduled from follow-on schedule check
[2025-05-04T00:19:18.077+0000] {local_task_job_runner.py:245} INFO - ::endgroup::
