[2025-05-04T01:38:33.173+0000] {local_task_job_runner.py:123} INFO - ::group::Pre task execution logs
[2025-05-04T01:38:33.208+0000] {taskinstance.py:2612} INFO - Dependencies all met for dep_context=non-requeueable deps ti=<TaskInstance: tweet_sentiment_dag.collect_tweets manual__2025-05-04T01:38:29.692092+00:00 [queued]>
[2025-05-04T01:38:33.224+0000] {taskinstance.py:2612} INFO - Dependencies all met for dep_context=requeueable deps ti=<TaskInstance: tweet_sentiment_dag.collect_tweets manual__2025-05-04T01:38:29.692092+00:00 [queued]>
[2025-05-04T01:38:33.225+0000] {taskinstance.py:2865} INFO - Starting attempt 1 of 1
[2025-05-04T01:38:33.255+0000] {taskinstance.py:2888} INFO - Executing <Task(BashOperator): collect_tweets> on 2025-05-04 01:38:29.692092+00:00
[2025-05-04T01:38:33.267+0000] {standard_task_runner.py:72} INFO - Started process 4779 to run task
[2025-05-04T01:38:33.271+0000] {standard_task_runner.py:104} INFO - Running: ['***', 'tasks', 'run', 'tweet_sentiment_dag', 'collect_tweets', 'manual__2025-05-04T01:38:29.692092+00:00', '--job-id', '94', '--raw', '--subdir', 'DAGS_FOLDER/tweet_sentiment_dag.py', '--cfg-path', '/tmp/tmpy2bzae98']
[2025-05-04T01:38:33.274+0000] {standard_task_runner.py:105} INFO - Job 94: Subtask collect_tweets
[2025-05-04T01:38:33.335+0000] {task_command.py:467} INFO - Running <TaskInstance: tweet_sentiment_dag.collect_tweets manual__2025-05-04T01:38:29.692092+00:00 [running]> on host 7f722b744d3e
[2025-05-04T01:38:33.465+0000] {taskinstance.py:3131} INFO - Exporting env vars: AIRFLOW_CTX_DAG_OWNER='***' AIRFLOW_CTX_DAG_ID='tweet_sentiment_dag' AIRFLOW_CTX_TASK_ID='collect_tweets' AIRFLOW_CTX_EXECUTION_DATE='2025-05-04T01:38:29.692092+00:00' AIRFLOW_CTX_TRY_NUMBER='1' AIRFLOW_CTX_DAG_RUN_ID='manual__2025-05-04T01:38:29.692092+00:00'
[2025-05-04T01:38:33.468+0000] {taskinstance.py:731} INFO - ::endgroup::
[2025-05-04T01:38:33.529+0000] {subprocess.py:63} INFO - Tmp dir root location: /tmp
[2025-05-04T01:38:33.543+0000] {subprocess.py:75} INFO - Running command: ['/usr/bin/bash', '-c', 'python /opt/***/ingestion/tweet_collector.py']
[2025-05-04T01:38:33.558+0000] {subprocess.py:86} INFO - Output:
[2025-05-04T01:38:34.870+0000] {subprocess.py:93} INFO - Traceback (most recent call last):
[2025-05-04T01:38:34.878+0000] {subprocess.py:93} INFO -   File "/home/***/.local/lib/python3.9/site-packages/urllib3/connection.py", line 174, in _new_conn
[2025-05-04T01:38:34.879+0000] {subprocess.py:93} INFO -     conn = connection.create_connection(
[2025-05-04T01:38:34.880+0000] {subprocess.py:93} INFO -   File "/home/***/.local/lib/python3.9/site-packages/urllib3/util/connection.py", line 72, in create_connection
[2025-05-04T01:38:34.881+0000] {subprocess.py:93} INFO -     for res in socket.getaddrinfo(host, port, family, socket.SOCK_STREAM):
[2025-05-04T01:38:34.882+0000] {subprocess.py:93} INFO -   File "/usr/local/lib/python3.9/socket.py", line 954, in getaddrinfo
[2025-05-04T01:38:34.883+0000] {subprocess.py:93} INFO -     for res in _socket.getaddrinfo(host, port, family, type, proto, flags):
[2025-05-04T01:38:34.884+0000] {subprocess.py:93} INFO - socket.gaierror: [Errno -3] Temporary failure in name resolution
[2025-05-04T01:38:34.885+0000] {subprocess.py:93} INFO - 
[2025-05-04T01:38:34.886+0000] {subprocess.py:93} INFO - During handling of the above exception, another exception occurred:
[2025-05-04T01:38:34.887+0000] {subprocess.py:93} INFO - 
[2025-05-04T01:38:34.888+0000] {subprocess.py:93} INFO - Traceback (most recent call last):
[2025-05-04T01:38:34.890+0000] {subprocess.py:93} INFO -   File "/home/***/.local/lib/python3.9/site-packages/urllib3/connectionpool.py", line 716, in urlopen
[2025-05-04T01:38:34.891+0000] {subprocess.py:93} INFO -     httplib_response = self._make_request(
[2025-05-04T01:38:34.892+0000] {subprocess.py:93} INFO -   File "/home/***/.local/lib/python3.9/site-packages/urllib3/connectionpool.py", line 404, in _make_request
[2025-05-04T01:38:34.893+0000] {subprocess.py:93} INFO -     self._validate_conn(conn)
[2025-05-04T01:38:34.894+0000] {subprocess.py:93} INFO -   File "/home/***/.local/lib/python3.9/site-packages/urllib3/connectionpool.py", line 1061, in _validate_conn
[2025-05-04T01:38:34.894+0000] {subprocess.py:93} INFO -     conn.connect()
[2025-05-04T01:38:34.895+0000] {subprocess.py:93} INFO -   File "/home/***/.local/lib/python3.9/site-packages/urllib3/connection.py", line 363, in connect
[2025-05-04T01:38:34.897+0000] {subprocess.py:93} INFO -     self.sock = conn = self._new_conn()
[2025-05-04T01:38:34.898+0000] {subprocess.py:93} INFO -   File "/home/***/.local/lib/python3.9/site-packages/urllib3/connection.py", line 186, in _new_conn
[2025-05-04T01:38:34.899+0000] {subprocess.py:93} INFO -     raise NewConnectionError(
[2025-05-04T01:38:34.899+0000] {subprocess.py:93} INFO - urllib3.exceptions.NewConnectionError: <urllib3.connection.HTTPSConnection object at 0x7f3e84c4aaf0>: Failed to establish a new connection: [Errno -3] Temporary failure in name resolution
[2025-05-04T01:38:34.901+0000] {subprocess.py:93} INFO - 
[2025-05-04T01:38:34.902+0000] {subprocess.py:93} INFO - During handling of the above exception, another exception occurred:
[2025-05-04T01:38:34.903+0000] {subprocess.py:93} INFO - 
[2025-05-04T01:38:34.904+0000] {subprocess.py:93} INFO - Traceback (most recent call last):
[2025-05-04T01:38:34.905+0000] {subprocess.py:93} INFO -   File "/home/***/.local/lib/python3.9/site-packages/requests/adapters.py", line 667, in send
[2025-05-04T01:38:34.907+0000] {subprocess.py:93} INFO -     resp = conn.urlopen(
[2025-05-04T01:38:34.908+0000] {subprocess.py:93} INFO -   File "/home/***/.local/lib/python3.9/site-packages/urllib3/connectionpool.py", line 802, in urlopen
[2025-05-04T01:38:34.908+0000] {subprocess.py:93} INFO -     retries = retries.increment(
[2025-05-04T01:38:34.909+0000] {subprocess.py:93} INFO -   File "/home/***/.local/lib/python3.9/site-packages/urllib3/util/retry.py", line 594, in increment
[2025-05-04T01:38:34.911+0000] {subprocess.py:93} INFO -     raise MaxRetryError(_pool, url, error or ResponseError(cause))
[2025-05-04T01:38:34.912+0000] {subprocess.py:93} INFO - urllib3.exceptions.MaxRetryError: HTTPSConnectionPool(host='api.twitter.com', port=443): Max retries exceeded with url: /2/tweets/search/recent?tweet.fields=created_at&max_results=10&query=Tesla+-is%3Aretweet+lang%3Aen (Caused by NewConnectionError('<urllib3.connection.HTTPSConnection object at 0x7f3e84c4aaf0>: Failed to establish a new connection: [Errno -3] Temporary failure in name resolution'))
[2025-05-04T01:38:34.913+0000] {subprocess.py:93} INFO - 
[2025-05-04T01:38:34.914+0000] {subprocess.py:93} INFO - During handling of the above exception, another exception occurred:
[2025-05-04T01:38:34.914+0000] {subprocess.py:93} INFO - 
[2025-05-04T01:38:34.915+0000] {subprocess.py:93} INFO - Traceback (most recent call last):
[2025-05-04T01:38:34.916+0000] {subprocess.py:93} INFO -   File "/opt/***/ingestion/tweet_collector.py", line 8, in <module>
[2025-05-04T01:38:34.917+0000] {subprocess.py:93} INFO -     tweets = client.search_recent_tweets(query=query, tweet_fields=['created_at'], max_results=10)
[2025-05-04T01:38:34.918+0000] {subprocess.py:93} INFO -   File "/home/***/.local/lib/python3.9/site-packages/tweepy/client.py", line 1270, in search_recent_tweets
[2025-05-04T01:38:34.919+0000] {subprocess.py:93} INFO -     return self._make_request(
[2025-05-04T01:38:34.920+0000] {subprocess.py:93} INFO -   File "/home/***/.local/lib/python3.9/site-packages/tweepy/client.py", line 129, in _make_request
[2025-05-04T01:38:34.921+0000] {subprocess.py:93} INFO -     response = self.request(method, route, params=request_params,
[2025-05-04T01:38:34.922+0000] {subprocess.py:93} INFO -   File "/home/***/.local/lib/python3.9/site-packages/tweepy/client.py", line 84, in request
[2025-05-04T01:38:34.923+0000] {subprocess.py:93} INFO -     with self.session.request(
[2025-05-04T01:38:34.923+0000] {subprocess.py:93} INFO -   File "/home/***/.local/lib/python3.9/site-packages/requests/sessions.py", line 589, in request
[2025-05-04T01:38:34.924+0000] {subprocess.py:93} INFO -     resp = self.send(prep, **send_kwargs)
[2025-05-04T01:38:34.925+0000] {subprocess.py:93} INFO -   File "/home/***/.local/lib/python3.9/site-packages/requests/sessions.py", line 703, in send
[2025-05-04T01:38:34.926+0000] {subprocess.py:93} INFO -     r = adapter.send(request, **kwargs)
[2025-05-04T01:38:34.927+0000] {subprocess.py:93} INFO -   File "/home/***/.local/lib/python3.9/site-packages/requests/adapters.py", line 700, in send
[2025-05-04T01:38:34.928+0000] {subprocess.py:93} INFO -     raise ConnectionError(e, request=request)
[2025-05-04T01:38:34.928+0000] {subprocess.py:93} INFO - requests.exceptions.ConnectionError: HTTPSConnectionPool(host='api.twitter.com', port=443): Max retries exceeded with url: /2/tweets/search/recent?tweet.fields=created_at&max_results=10&query=Tesla+-is%3Aretweet+lang%3Aen (Caused by NewConnectionError('<urllib3.connection.HTTPSConnection object at 0x7f3e84c4aaf0>: Failed to establish a new connection: [Errno -3] Temporary failure in name resolution'))
[2025-05-04T01:38:34.930+0000] {subprocess.py:97} INFO - Command exited with return code 1
[2025-05-04T01:38:34.945+0000] {taskinstance.py:3310} ERROR - Task failed with exception
Traceback (most recent call last):
  File "/home/airflow/.local/lib/python3.9/site-packages/airflow/models/taskinstance.py", line 767, in _execute_task
    result = _execute_callable(context=context, **execute_callable_kwargs)
  File "/home/airflow/.local/lib/python3.9/site-packages/airflow/models/taskinstance.py", line 733, in _execute_callable
    return ExecutionCallableRunner(
  File "/home/airflow/.local/lib/python3.9/site-packages/airflow/utils/operator_helpers.py", line 252, in run
    return self.func(*args, **kwargs)
  File "/home/airflow/.local/lib/python3.9/site-packages/airflow/models/baseoperator.py", line 406, in wrapper
    return func(self, *args, **kwargs)
  File "/home/airflow/.local/lib/python3.9/site-packages/airflow/operators/bash.py", line 249, in execute
    raise AirflowException(
airflow.exceptions.AirflowException: Bash command failed. The command returned a non-zero exit code 1.
[2025-05-04T01:38:34.960+0000] {taskinstance.py:1225} INFO - Marking task as FAILED. dag_id=tweet_sentiment_dag, task_id=collect_tweets, run_id=manual__2025-05-04T01:38:29.692092+00:00, execution_date=20250504T013829, start_date=20250504T013833, end_date=20250504T013834
[2025-05-04T01:38:34.984+0000] {taskinstance.py:340} INFO - ::group::Post task execution logs
[2025-05-04T01:38:34.985+0000] {standard_task_runner.py:124} ERROR - Failed to execute job 94 for task collect_tweets (Bash command failed. The command returned a non-zero exit code 1.; 4779)
Traceback (most recent call last):
  File "/home/airflow/.local/lib/python3.9/site-packages/airflow/task/task_runner/standard_task_runner.py", line 117, in _start_by_fork
    ret = args.func(args, dag=self.dag)
  File "/home/airflow/.local/lib/python3.9/site-packages/airflow/cli/cli_config.py", line 49, in command
    return func(*args, **kwargs)
  File "/home/airflow/.local/lib/python3.9/site-packages/airflow/utils/cli.py", line 115, in wrapper
    return f(*args, **kwargs)
  File "/home/airflow/.local/lib/python3.9/site-packages/airflow/cli/commands/task_command.py", line 483, in task_run
    task_return_code = _run_task_by_selected_method(args, _dag, ti)
  File "/home/airflow/.local/lib/python3.9/site-packages/airflow/cli/commands/task_command.py", line 256, in _run_task_by_selected_method
    return _run_raw_task(args, ti)
  File "/home/airflow/.local/lib/python3.9/site-packages/airflow/cli/commands/task_command.py", line 341, in _run_raw_task
    return ti._run_raw_task(
  File "/home/airflow/.local/lib/python3.9/site-packages/airflow/utils/session.py", line 97, in wrapper
    return func(*args, session=session, **kwargs)
  File "/home/airflow/.local/lib/python3.9/site-packages/airflow/models/taskinstance.py", line 3004, in _run_raw_task
    return _run_raw_task(
  File "/home/airflow/.local/lib/python3.9/site-packages/airflow/models/taskinstance.py", line 273, in _run_raw_task
    TaskInstance._execute_task_with_callbacks(
  File "/home/airflow/.local/lib/python3.9/site-packages/airflow/models/taskinstance.py", line 3158, in _execute_task_with_callbacks
    result = self._execute_task(context, task_orig)
  File "/home/airflow/.local/lib/python3.9/site-packages/airflow/models/taskinstance.py", line 3182, in _execute_task
    return _execute_task(self, context, task_orig)
  File "/home/airflow/.local/lib/python3.9/site-packages/airflow/models/taskinstance.py", line 767, in _execute_task
    result = _execute_callable(context=context, **execute_callable_kwargs)
  File "/home/airflow/.local/lib/python3.9/site-packages/airflow/models/taskinstance.py", line 733, in _execute_callable
    return ExecutionCallableRunner(
  File "/home/airflow/.local/lib/python3.9/site-packages/airflow/utils/operator_helpers.py", line 252, in run
    return self.func(*args, **kwargs)
  File "/home/airflow/.local/lib/python3.9/site-packages/airflow/models/baseoperator.py", line 406, in wrapper
    return func(self, *args, **kwargs)
  File "/home/airflow/.local/lib/python3.9/site-packages/airflow/operators/bash.py", line 249, in execute
    raise AirflowException(
airflow.exceptions.AirflowException: Bash command failed. The command returned a non-zero exit code 1.
[2025-05-04T01:38:35.021+0000] {local_task_job_runner.py:266} INFO - Task exited with return code 1
[2025-05-04T01:38:35.063+0000] {taskinstance.py:3900} INFO - 0 downstream tasks scheduled from follow-on schedule check
[2025-05-04T01:38:35.069+0000] {local_task_job_runner.py:245} INFO - ::endgroup::
