[2025-05-07T00:37:19.399+0000] {local_task_job_runner.py:123} INFO - ::group::Pre task execution logs
[2025-05-07T00:37:19.434+0000] {taskinstance.py:2612} INFO - Dependencies all met for dep_context=non-requeueable deps ti=<TaskInstance: BuildELT_dbt.dbt_run manual__2025-05-07T00:37:16.716937+00:00 [queued]>
[2025-05-07T00:37:19.455+0000] {taskinstance.py:2612} INFO - Dependencies all met for dep_context=requeueable deps ti=<TaskInstance: BuildELT_dbt.dbt_run manual__2025-05-07T00:37:16.716937+00:00 [queued]>
[2025-05-07T00:37:19.457+0000] {taskinstance.py:2865} INFO - Starting attempt 1 of 1
[2025-05-07T00:37:19.485+0000] {taskinstance.py:2888} INFO - Executing <Task(BashOperator): dbt_run> on 2025-05-07 00:37:16.716937+00:00
[2025-05-07T00:37:19.496+0000] {standard_task_runner.py:72} INFO - Started process 788 to run task
[2025-05-07T00:37:19.502+0000] {standard_task_runner.py:104} INFO - Running: ['***', 'tasks', 'run', 'BuildELT_dbt', 'dbt_run', 'manual__2025-05-07T00:37:16.716937+00:00', '--job-id', '43', '--raw', '--subdir', 'DAGS_FOLDER/build_elt_with_dbt.py', '--cfg-path', '/tmp/tmpw1ozjsnv']
[2025-05-07T00:37:19.509+0000] {standard_task_runner.py:105} INFO - Job 43: Subtask dbt_run
[2025-05-07T00:37:19.592+0000] {task_command.py:467} INFO - Running <TaskInstance: BuildELT_dbt.dbt_run manual__2025-05-07T00:37:16.716937+00:00 [running]> on host 55fd2231a72d
[2025-05-07T00:37:19.775+0000] {taskinstance.py:3131} INFO - Exporting env vars: AIRFLOW_CTX_DAG_OWNER='***' AIRFLOW_CTX_DAG_ID='BuildELT_dbt' AIRFLOW_CTX_TASK_ID='dbt_run' AIRFLOW_CTX_EXECUTION_DATE='2025-05-07T00:37:16.716937+00:00' AIRFLOW_CTX_TRY_NUMBER='1' AIRFLOW_CTX_DAG_RUN_ID='manual__2025-05-07T00:37:16.716937+00:00'
[2025-05-07T00:37:19.780+0000] {taskinstance.py:731} INFO - ::endgroup::
[2025-05-07T00:37:19.931+0000] {subprocess.py:63} INFO - Tmp dir root location: /tmp
[2025-05-07T00:37:19.942+0000] {subprocess.py:75} INFO - Running command: ['/usr/bin/bash', '-c', '/home/***/.local/bin/dbt run --profiles-dir /opt/***/tesla_project --project-dir /opt/***/tesla_project']
[2025-05-07T00:37:19.969+0000] {subprocess.py:86} INFO - Output:
[2025-05-07T00:37:26.804+0000] {subprocess.py:93} INFO - [0m00:37:26  Running with dbt=1.8.7
[2025-05-07T00:37:31.351+0000] {subprocess.py:93} INFO - [0m00:37:31  Registered adapter: snowflake=1.8.1
[2025-05-07T00:37:32.892+0000] {subprocess.py:93} INFO - [0m00:37:32  [[33mWARNING[0m]: Configuration paths exist in your dbt_project.yml file which do not apply to any resources.
[2025-05-07T00:37:32.893+0000] {subprocess.py:93} INFO - There are 1 unused configuration paths:
[2025-05-07T00:37:32.894+0000] {subprocess.py:93} INFO - - models.tesla_project.example
[2025-05-07T00:37:33.111+0000] {subprocess.py:93} INFO - [0m00:37:33  Found 3 models, 1 snapshot, 1 seed, 1 source, 459 macros
[2025-05-07T00:37:33.114+0000] {subprocess.py:93} INFO - [0m00:37:33
[2025-05-07T00:37:36.641+0000] {subprocess.py:93} INFO - [0m00:37:36  Concurrency: 1 threads (target='dev')
[2025-05-07T00:37:36.642+0000] {subprocess.py:93} INFO - [0m00:37:36
[2025-05-07T00:37:36.654+0000] {subprocess.py:93} INFO - [0m00:37:36  1 of 3 START sql table model analytics.input ................................... [RUN]
[2025-05-07T00:37:40.155+0000] {subprocess.py:93} INFO - [0m00:37:40  1 of 3 OK created sql table model analytics.input .............................. [[32mSUCCESS 1[0m in 3.50s]
[2025-05-07T00:37:40.161+0000] {subprocess.py:93} INFO - [0m00:37:40  2 of 3 START sql table model analytics.sentiment_features_final ................ [RUN]
[2025-05-07T00:37:42.068+0000] {subprocess.py:93} INFO - [0m00:37:42  2 of 3 OK created sql table model analytics.sentiment_features_final ........... [[32mSUCCESS 1[0m in 1.90s]
[2025-05-07T00:37:42.073+0000] {subprocess.py:93} INFO - [0m00:37:42  3 of 3 START sql table model analytics.output .................................. [RUN]
[2025-05-07T00:37:42.803+0000] {subprocess.py:93} INFO - [0m00:37:42  3 of 3 ERROR creating sql table model analytics.output ......................... [[31mERROR[0m in 0.73s]
[2025-05-07T00:37:42.808+0000] {subprocess.py:93} INFO - [0m00:37:42
[2025-05-07T00:37:42.810+0000] {subprocess.py:93} INFO - [0m00:37:42  Finished running 3 table models in 0 hours 0 minutes and 9.69 seconds (9.69s).
[2025-05-07T00:37:42.872+0000] {subprocess.py:93} INFO - [0m00:37:42
[2025-05-07T00:37:42.873+0000] {subprocess.py:93} INFO - [0m00:37:42  [31mCompleted with 1 error and 0 warnings:[0m
[2025-05-07T00:37:42.874+0000] {subprocess.py:93} INFO - [0m00:37:42
[2025-05-07T00:37:42.875+0000] {subprocess.py:93} INFO - [0m00:37:42    Database Error in model output (models/output/output.sql)
[2025-05-07T00:37:42.876+0000] {subprocess.py:93} INFO -   002003 (42S02): SQL compilation error:
[2025-05-07T00:37:42.877+0000] {subprocess.py:93} INFO -   Object 'DEV.ANALYTICS.REGRESSION_METRICS' does not exist or not authorized.
[2025-05-07T00:37:42.878+0000] {subprocess.py:93} INFO -   compiled code at target/run/tesla_project/models/output/output.sql
[2025-05-07T00:37:42.879+0000] {subprocess.py:93} INFO - [0m00:37:42
[2025-05-07T00:37:42.880+0000] {subprocess.py:93} INFO - [0m00:37:42  Done. PASS=2 WARN=0 ERROR=1 SKIP=0 TOTAL=3
[2025-05-07T00:37:44.109+0000] {subprocess.py:97} INFO - Command exited with return code 1
[2025-05-07T00:37:44.164+0000] {taskinstance.py:3310} ERROR - Task failed with exception
Traceback (most recent call last):
  File "/home/airflow/.local/lib/python3.9/site-packages/airflow/models/taskinstance.py", line 767, in _execute_task
    result = _execute_callable(context=context, **execute_callable_kwargs)
  File "/home/airflow/.local/lib/python3.9/site-packages/airflow/models/taskinstance.py", line 733, in _execute_callable
    return ExecutionCallableRunner(
  File "/home/airflow/.local/lib/python3.9/site-packages/airflow/utils/operator_helpers.py", line 252, in run
    return self.func(*args, **kwargs)
  File "/home/airflow/.local/lib/python3.9/site-packages/airflow/models/baseoperator.py", line 406, in wrapper
    return func(self, *args, **kwargs)
  File "/home/airflow/.local/lib/python3.9/site-packages/airflow/operators/bash.py", line 249, in execute
    raise AirflowException(
airflow.exceptions.AirflowException: Bash command failed. The command returned a non-zero exit code 1.
[2025-05-07T00:37:44.177+0000] {taskinstance.py:1225} INFO - Marking task as FAILED. dag_id=BuildELT_dbt, task_id=dbt_run, run_id=manual__2025-05-07T00:37:16.716937+00:00, execution_date=20250507T003716, start_date=20250507T003719, end_date=20250507T003744
[2025-05-07T00:37:44.238+0000] {taskinstance.py:340} INFO - ::group::Post task execution logs
[2025-05-07T00:37:44.241+0000] {standard_task_runner.py:124} ERROR - Failed to execute job 43 for task dbt_run (Bash command failed. The command returned a non-zero exit code 1.; 788)
Traceback (most recent call last):
  File "/home/airflow/.local/lib/python3.9/site-packages/airflow/task/task_runner/standard_task_runner.py", line 117, in _start_by_fork
    ret = args.func(args, dag=self.dag)
  File "/home/airflow/.local/lib/python3.9/site-packages/airflow/cli/cli_config.py", line 49, in command
    return func(*args, **kwargs)
  File "/home/airflow/.local/lib/python3.9/site-packages/airflow/utils/cli.py", line 115, in wrapper
    return f(*args, **kwargs)
  File "/home/airflow/.local/lib/python3.9/site-packages/airflow/cli/commands/task_command.py", line 483, in task_run
    task_return_code = _run_task_by_selected_method(args, _dag, ti)
  File "/home/airflow/.local/lib/python3.9/site-packages/airflow/cli/commands/task_command.py", line 256, in _run_task_by_selected_method
    return _run_raw_task(args, ti)
  File "/home/airflow/.local/lib/python3.9/site-packages/airflow/cli/commands/task_command.py", line 341, in _run_raw_task
    return ti._run_raw_task(
  File "/home/airflow/.local/lib/python3.9/site-packages/airflow/utils/session.py", line 97, in wrapper
    return func(*args, session=session, **kwargs)
  File "/home/airflow/.local/lib/python3.9/site-packages/airflow/models/taskinstance.py", line 3004, in _run_raw_task
    return _run_raw_task(
  File "/home/airflow/.local/lib/python3.9/site-packages/airflow/models/taskinstance.py", line 273, in _run_raw_task
    TaskInstance._execute_task_with_callbacks(
  File "/home/airflow/.local/lib/python3.9/site-packages/airflow/models/taskinstance.py", line 3158, in _execute_task_with_callbacks
    result = self._execute_task(context, task_orig)
  File "/home/airflow/.local/lib/python3.9/site-packages/airflow/models/taskinstance.py", line 3182, in _execute_task
    return _execute_task(self, context, task_orig)
  File "/home/airflow/.local/lib/python3.9/site-packages/airflow/models/taskinstance.py", line 767, in _execute_task
    result = _execute_callable(context=context, **execute_callable_kwargs)
  File "/home/airflow/.local/lib/python3.9/site-packages/airflow/models/taskinstance.py", line 733, in _execute_callable
    return ExecutionCallableRunner(
  File "/home/airflow/.local/lib/python3.9/site-packages/airflow/utils/operator_helpers.py", line 252, in run
    return self.func(*args, **kwargs)
  File "/home/airflow/.local/lib/python3.9/site-packages/airflow/models/baseoperator.py", line 406, in wrapper
    return func(self, *args, **kwargs)
  File "/home/airflow/.local/lib/python3.9/site-packages/airflow/operators/bash.py", line 249, in execute
    raise AirflowException(
airflow.exceptions.AirflowException: Bash command failed. The command returned a non-zero exit code 1.
[2025-05-07T00:37:44.280+0000] {local_task_job_runner.py:266} INFO - Task exited with return code 1
[2025-05-07T00:37:44.311+0000] {local_task_job_runner.py:245} INFO - ::endgroup::
