[2025-05-06T03:44:21.759+0000] {local_task_job_runner.py:123} INFO - ::group::Pre task execution logs
[2025-05-06T03:44:21.784+0000] {taskinstance.py:2612} INFO - Dependencies all met for dep_context=non-requeueable deps ti=<TaskInstance: BuildELT_dbt.dbt_run manual__2025-05-06T03:44:20.491714+00:00 [queued]>
[2025-05-06T03:44:21.797+0000] {taskinstance.py:2612} INFO - Dependencies all met for dep_context=requeueable deps ti=<TaskInstance: BuildELT_dbt.dbt_run manual__2025-05-06T03:44:20.491714+00:00 [queued]>
[2025-05-06T03:44:21.799+0000] {taskinstance.py:2865} INFO - Starting attempt 1 of 1
[2025-05-06T03:44:21.825+0000] {taskinstance.py:2888} INFO - Executing <Task(BashOperator): dbt_run> on 2025-05-06 03:44:20.491714+00:00
[2025-05-06T03:44:21.833+0000] {standard_task_runner.py:72} INFO - Started process 2551 to run task
[2025-05-06T03:44:21.839+0000] {standard_task_runner.py:104} INFO - Running: ['***', 'tasks', 'run', 'BuildELT_dbt', 'dbt_run', 'manual__2025-05-06T03:44:20.491714+00:00', '--job-id', '32', '--raw', '--subdir', 'DAGS_FOLDER/build_elt_with_dbt.py', '--cfg-path', '/tmp/tmpcp6bnts2']
[2025-05-06T03:44:21.847+0000] {standard_task_runner.py:105} INFO - Job 32: Subtask dbt_run
[2025-05-06T03:44:21.925+0000] {task_command.py:467} INFO - Running <TaskInstance: BuildELT_dbt.dbt_run manual__2025-05-06T03:44:20.491714+00:00 [running]> on host 4bf74f6ca137
[2025-05-06T03:44:22.077+0000] {taskinstance.py:3131} INFO - Exporting env vars: AIRFLOW_CTX_DAG_OWNER='***' AIRFLOW_CTX_DAG_ID='BuildELT_dbt' AIRFLOW_CTX_TASK_ID='dbt_run' AIRFLOW_CTX_EXECUTION_DATE='2025-05-06T03:44:20.491714+00:00' AIRFLOW_CTX_TRY_NUMBER='1' AIRFLOW_CTX_DAG_RUN_ID='manual__2025-05-06T03:44:20.491714+00:00'
[2025-05-06T03:44:22.080+0000] {taskinstance.py:731} INFO - ::endgroup::
[2025-05-06T03:44:22.119+0000] {subprocess.py:63} INFO - Tmp dir root location: /tmp
[2025-05-06T03:44:22.123+0000] {subprocess.py:75} INFO - Running command: ['/usr/bin/bash', '-c', '/home/***/.local/bin/dbt run --profiles-dir /opt/***/tesla_project --project-dir /opt/***/tesla_project']
[2025-05-06T03:44:22.139+0000] {subprocess.py:86} INFO - Output:
[2025-05-06T03:44:24.751+0000] {subprocess.py:93} INFO - [0m03:44:24  Running with dbt=1.8.7
[2025-05-06T03:44:26.305+0000] {subprocess.py:93} INFO - [0m03:44:26  Registered adapter: snowflake=1.8.1
[2025-05-06T03:44:27.818+0000] {subprocess.py:93} INFO - [0m03:44:27  [[33mWARNING[0m]: Configuration paths exist in your dbt_project.yml file which do not apply to any resources.
[2025-05-06T03:44:27.819+0000] {subprocess.py:93} INFO - There are 1 unused configuration paths:
[2025-05-06T03:44:27.820+0000] {subprocess.py:93} INFO - - models.tesla_project.example
[2025-05-06T03:44:28.035+0000] {subprocess.py:93} INFO - [0m03:44:28  Found 3 models, 1 snapshot, 1 source, 459 macros
[2025-05-06T03:44:28.039+0000] {subprocess.py:93} INFO - [0m03:44:28
[2025-05-06T03:44:32.620+0000] {subprocess.py:93} INFO - [0m03:44:32  Concurrency: 1 threads (target='dev')
[2025-05-06T03:44:32.622+0000] {subprocess.py:93} INFO - [0m03:44:32
[2025-05-06T03:44:32.633+0000] {subprocess.py:93} INFO - [0m03:44:32  1 of 3 START sql table model analytics.input ................................... [RUN]
[2025-05-06T03:44:34.033+0000] {subprocess.py:93} INFO - [0m03:44:34  1 of 3 ERROR creating sql table model analytics.input .......................... [[31mERROR[0m in 1.39s]
[2025-05-06T03:44:34.043+0000] {subprocess.py:93} INFO - [0m03:44:34  2 of 3 SKIP relation analytics.sentiment_features_final ........................ [[33mSKIP[0m]
[2025-05-06T03:44:34.053+0000] {subprocess.py:93} INFO - [0m03:44:34  3 of 3 SKIP relation analytics.output .......................................... [[33mSKIP[0m]
[2025-05-06T03:44:34.067+0000] {subprocess.py:93} INFO - [0m03:44:34
[2025-05-06T03:44:34.069+0000] {subprocess.py:93} INFO - [0m03:44:34  Finished running 3 table models in 0 hours 0 minutes and 6.03 seconds (6.03s).
[2025-05-06T03:44:34.165+0000] {subprocess.py:93} INFO - [0m03:44:34
[2025-05-06T03:44:34.166+0000] {subprocess.py:93} INFO - [0m03:44:34  [31mCompleted with 1 error and 0 warnings:[0m
[2025-05-06T03:44:34.167+0000] {subprocess.py:93} INFO - [0m03:44:34
[2025-05-06T03:44:34.168+0000] {subprocess.py:93} INFO - [0m03:44:34    Database Error in model input (models/input/input.sql)
[2025-05-06T03:44:34.169+0000] {subprocess.py:93} INFO -   002003 (42S02): SQL compilation error:
[2025-05-06T03:44:34.170+0000] {subprocess.py:93} INFO -   Object 'FINAL_RAW_DATA' does not exist or not authorized.
[2025-05-06T03:44:34.171+0000] {subprocess.py:93} INFO -   compiled code at target/run/tesla_project/models/input/input.sql
[2025-05-06T03:44:34.171+0000] {subprocess.py:93} INFO - [0m03:44:34
[2025-05-06T03:44:34.172+0000] {subprocess.py:93} INFO - [0m03:44:34  Done. PASS=0 WARN=0 ERROR=1 SKIP=2 TOTAL=3
[2025-05-06T03:44:35.186+0000] {subprocess.py:97} INFO - Command exited with return code 1
[2025-05-06T03:44:35.206+0000] {taskinstance.py:3310} ERROR - Task failed with exception
Traceback (most recent call last):
  File "/home/airflow/.local/lib/python3.9/site-packages/airflow/models/taskinstance.py", line 767, in _execute_task
    result = _execute_callable(context=context, **execute_callable_kwargs)
  File "/home/airflow/.local/lib/python3.9/site-packages/airflow/models/taskinstance.py", line 733, in _execute_callable
    return ExecutionCallableRunner(
  File "/home/airflow/.local/lib/python3.9/site-packages/airflow/utils/operator_helpers.py", line 252, in run
    return self.func(*args, **kwargs)
  File "/home/airflow/.local/lib/python3.9/site-packages/airflow/models/baseoperator.py", line 406, in wrapper
    return func(self, *args, **kwargs)
  File "/home/airflow/.local/lib/python3.9/site-packages/airflow/operators/bash.py", line 249, in execute
    raise AirflowException(
airflow.exceptions.AirflowException: Bash command failed. The command returned a non-zero exit code 1.
[2025-05-06T03:44:35.220+0000] {taskinstance.py:1225} INFO - Marking task as FAILED. dag_id=BuildELT_dbt, task_id=dbt_run, run_id=manual__2025-05-06T03:44:20.491714+00:00, execution_date=20250506T034420, start_date=20250506T034421, end_date=20250506T034435
[2025-05-06T03:44:35.237+0000] {taskinstance.py:340} INFO - ::group::Post task execution logs
[2025-05-06T03:44:35.238+0000] {standard_task_runner.py:124} ERROR - Failed to execute job 32 for task dbt_run (Bash command failed. The command returned a non-zero exit code 1.; 2551)
Traceback (most recent call last):
  File "/home/airflow/.local/lib/python3.9/site-packages/airflow/task/task_runner/standard_task_runner.py", line 117, in _start_by_fork
    ret = args.func(args, dag=self.dag)
  File "/home/airflow/.local/lib/python3.9/site-packages/airflow/cli/cli_config.py", line 49, in command
    return func(*args, **kwargs)
  File "/home/airflow/.local/lib/python3.9/site-packages/airflow/utils/cli.py", line 115, in wrapper
    return f(*args, **kwargs)
  File "/home/airflow/.local/lib/python3.9/site-packages/airflow/cli/commands/task_command.py", line 483, in task_run
    task_return_code = _run_task_by_selected_method(args, _dag, ti)
  File "/home/airflow/.local/lib/python3.9/site-packages/airflow/cli/commands/task_command.py", line 256, in _run_task_by_selected_method
    return _run_raw_task(args, ti)
  File "/home/airflow/.local/lib/python3.9/site-packages/airflow/cli/commands/task_command.py", line 341, in _run_raw_task
    return ti._run_raw_task(
  File "/home/airflow/.local/lib/python3.9/site-packages/airflow/utils/session.py", line 97, in wrapper
    return func(*args, session=session, **kwargs)
  File "/home/airflow/.local/lib/python3.9/site-packages/airflow/models/taskinstance.py", line 3004, in _run_raw_task
    return _run_raw_task(
  File "/home/airflow/.local/lib/python3.9/site-packages/airflow/models/taskinstance.py", line 273, in _run_raw_task
    TaskInstance._execute_task_with_callbacks(
  File "/home/airflow/.local/lib/python3.9/site-packages/airflow/models/taskinstance.py", line 3158, in _execute_task_with_callbacks
    result = self._execute_task(context, task_orig)
  File "/home/airflow/.local/lib/python3.9/site-packages/airflow/models/taskinstance.py", line 3182, in _execute_task
    return _execute_task(self, context, task_orig)
  File "/home/airflow/.local/lib/python3.9/site-packages/airflow/models/taskinstance.py", line 767, in _execute_task
    result = _execute_callable(context=context, **execute_callable_kwargs)
  File "/home/airflow/.local/lib/python3.9/site-packages/airflow/models/taskinstance.py", line 733, in _execute_callable
    return ExecutionCallableRunner(
  File "/home/airflow/.local/lib/python3.9/site-packages/airflow/utils/operator_helpers.py", line 252, in run
    return self.func(*args, **kwargs)
  File "/home/airflow/.local/lib/python3.9/site-packages/airflow/models/baseoperator.py", line 406, in wrapper
    return func(self, *args, **kwargs)
  File "/home/airflow/.local/lib/python3.9/site-packages/airflow/operators/bash.py", line 249, in execute
    raise AirflowException(
airflow.exceptions.AirflowException: Bash command failed. The command returned a non-zero exit code 1.
[2025-05-06T03:44:35.269+0000] {local_task_job_runner.py:266} INFO - Task exited with return code 1
[2025-05-06T03:44:35.314+0000] {taskinstance.py:3900} INFO - 0 downstream tasks scheduled from follow-on schedule check
[2025-05-06T03:44:35.324+0000] {local_task_job_runner.py:245} INFO - ::endgroup::
