[2025-05-04T00:13:02.818+0000] {local_task_job_runner.py:123} INFO - ::group::Pre task execution logs
[2025-05-04T00:13:02.867+0000] {taskinstance.py:2612} INFO - Dependencies all met for dep_context=non-requeueable deps ti=<TaskInstance: tweet_sentiment_dag.collect_tweets scheduled__2025-05-03T23:00:00+00:00 [queued]>
[2025-05-04T00:13:02.900+0000] {taskinstance.py:2612} INFO - Dependencies all met for dep_context=requeueable deps ti=<TaskInstance: tweet_sentiment_dag.collect_tweets scheduled__2025-05-03T23:00:00+00:00 [queued]>
[2025-05-04T00:13:02.907+0000] {taskinstance.py:2865} INFO - Starting attempt 1 of 1
[2025-05-04T00:13:02.931+0000] {taskinstance.py:2888} INFO - Executing <Task(BashOperator): collect_tweets> on 2025-05-03 23:00:00+00:00
[2025-05-04T00:13:02.951+0000] {standard_task_runner.py:72} INFO - Started process 1190 to run task
[2025-05-04T00:13:02.956+0000] {standard_task_runner.py:104} INFO - Running: ['***', 'tasks', 'run', 'tweet_sentiment_dag', 'collect_tweets', 'scheduled__2025-05-03T23:00:00+00:00', '--job-id', '86', '--raw', '--subdir', 'DAGS_FOLDER/tweet_sentiment_dag.py', '--cfg-path', '/tmp/tmpn9399mbc']
[2025-05-04T00:13:02.960+0000] {standard_task_runner.py:105} INFO - Job 86: Subtask collect_tweets
[2025-05-04T00:13:03.048+0000] {task_command.py:467} INFO - Running <TaskInstance: tweet_sentiment_dag.collect_tweets scheduled__2025-05-03T23:00:00+00:00 [running]> on host 7f722b744d3e
[2025-05-04T00:13:03.224+0000] {taskinstance.py:3131} INFO - Exporting env vars: AIRFLOW_CTX_DAG_OWNER='***' AIRFLOW_CTX_DAG_ID='tweet_sentiment_dag' AIRFLOW_CTX_TASK_ID='collect_tweets' AIRFLOW_CTX_EXECUTION_DATE='2025-05-03T23:00:00+00:00' AIRFLOW_CTX_TRY_NUMBER='1' AIRFLOW_CTX_DAG_RUN_ID='scheduled__2025-05-03T23:00:00+00:00'
[2025-05-04T00:13:03.225+0000] {taskinstance.py:731} INFO - ::endgroup::
[2025-05-04T00:13:03.271+0000] {subprocess.py:63} INFO - Tmp dir root location: /tmp
[2025-05-04T00:13:03.276+0000] {subprocess.py:75} INFO - Running command: ['/usr/bin/bash', '-c', 'python /opt/***/ingestion/tweet_collector.py']
[2025-05-04T00:13:03.330+0000] {subprocess.py:86} INFO - Output:
[2025-05-04T00:22:00.929+0000] {subprocess.py:93} INFO - Traceback (most recent call last):
[2025-05-04T00:22:01.013+0000] {subprocess.py:93} INFO -   File "/home/***/.local/lib/python3.9/site-packages/urllib3/connection.py", line 174, in _new_conn
[2025-05-04T00:22:01.020+0000] {subprocess.py:93} INFO -     conn = connection.create_connection(
[2025-05-04T00:22:01.021+0000] {subprocess.py:93} INFO -   File "/home/***/.local/lib/python3.9/site-packages/urllib3/util/connection.py", line 95, in create_connection
[2025-05-04T00:22:01.023+0000] {subprocess.py:93} INFO -     raise err
[2025-05-04T00:22:01.024+0000] {subprocess.py:93} INFO -   File "/home/***/.local/lib/python3.9/site-packages/urllib3/util/connection.py", line 85, in create_connection
[2025-05-04T00:22:01.026+0000] {subprocess.py:93} INFO -     sock.connect(sa)
[2025-05-04T00:22:01.027+0000] {subprocess.py:93} INFO - TimeoutError: [Errno 110] Connection timed out
[2025-05-04T00:22:01.028+0000] {subprocess.py:93} INFO - 
[2025-05-04T00:22:01.030+0000] {subprocess.py:93} INFO - During handling of the above exception, another exception occurred:
[2025-05-04T00:22:01.031+0000] {subprocess.py:93} INFO - 
[2025-05-04T00:22:01.032+0000] {subprocess.py:93} INFO - Traceback (most recent call last):
[2025-05-04T00:22:01.034+0000] {subprocess.py:93} INFO -   File "/home/***/.local/lib/python3.9/site-packages/urllib3/connectionpool.py", line 716, in urlopen
[2025-05-04T00:22:01.038+0000] {subprocess.py:93} INFO -     httplib_response = self._make_request(
[2025-05-04T00:22:01.039+0000] {subprocess.py:93} INFO -   File "/home/***/.local/lib/python3.9/site-packages/urllib3/connectionpool.py", line 404, in _make_request
[2025-05-04T00:22:01.040+0000] {subprocess.py:93} INFO -     self._validate_conn(conn)
[2025-05-04T00:22:01.041+0000] {subprocess.py:93} INFO -   File "/home/***/.local/lib/python3.9/site-packages/urllib3/connectionpool.py", line 1061, in _validate_conn
[2025-05-04T00:22:01.043+0000] {subprocess.py:93} INFO -     conn.connect()
[2025-05-04T00:22:01.045+0000] {subprocess.py:93} INFO -   File "/home/***/.local/lib/python3.9/site-packages/urllib3/connection.py", line 363, in connect
[2025-05-04T00:22:01.046+0000] {subprocess.py:93} INFO -     self.sock = conn = self._new_conn()
[2025-05-04T00:22:01.047+0000] {subprocess.py:93} INFO -   File "/home/***/.local/lib/python3.9/site-packages/urllib3/connection.py", line 186, in _new_conn
[2025-05-04T00:22:01.049+0000] {subprocess.py:93} INFO -     raise NewConnectionError(
[2025-05-04T00:22:01.051+0000] {subprocess.py:93} INFO - urllib3.exceptions.NewConnectionError: <urllib3.connection.HTTPSConnection object at 0x7f749b16baf0>: Failed to establish a new connection: [Errno 110] Connection timed out
[2025-05-04T00:22:01.052+0000] {subprocess.py:93} INFO - 
[2025-05-04T00:22:01.054+0000] {subprocess.py:93} INFO - During handling of the above exception, another exception occurred:
[2025-05-04T00:22:01.055+0000] {subprocess.py:93} INFO - 
[2025-05-04T00:22:01.056+0000] {subprocess.py:93} INFO - Traceback (most recent call last):
[2025-05-04T00:22:01.057+0000] {subprocess.py:93} INFO -   File "/home/***/.local/lib/python3.9/site-packages/requests/adapters.py", line 667, in send
[2025-05-04T00:22:01.057+0000] {subprocess.py:93} INFO -     resp = conn.urlopen(
[2025-05-04T00:22:01.059+0000] {subprocess.py:93} INFO -   File "/home/***/.local/lib/python3.9/site-packages/urllib3/connectionpool.py", line 802, in urlopen
[2025-05-04T00:22:01.060+0000] {subprocess.py:93} INFO -     retries = retries.increment(
[2025-05-04T00:22:01.062+0000] {subprocess.py:93} INFO -   File "/home/***/.local/lib/python3.9/site-packages/urllib3/util/retry.py", line 594, in increment
[2025-05-04T00:22:01.063+0000] {subprocess.py:93} INFO -     raise MaxRetryError(_pool, url, error or ResponseError(cause))
[2025-05-04T00:22:01.064+0000] {subprocess.py:93} INFO - urllib3.exceptions.MaxRetryError: HTTPSConnectionPool(host='api.twitter.com', port=443): Max retries exceeded with url: /2/tweets/search/recent?tweet.fields=created_at&max_results=10&query=Tesla+-is%3Aretweet+lang%3Aen (Caused by NewConnectionError('<urllib3.connection.HTTPSConnection object at 0x7f749b16baf0>: Failed to establish a new connection: [Errno 110] Connection timed out'))
[2025-05-04T00:22:01.065+0000] {subprocess.py:93} INFO - 
[2025-05-04T00:22:01.065+0000] {subprocess.py:93} INFO - During handling of the above exception, another exception occurred:
[2025-05-04T00:22:01.067+0000] {subprocess.py:93} INFO - 
[2025-05-04T00:22:01.068+0000] {subprocess.py:93} INFO - Traceback (most recent call last):
[2025-05-04T00:22:01.069+0000] {subprocess.py:93} INFO -   File "/opt/***/ingestion/tweet_collector.py", line 8, in <module>
[2025-05-04T00:22:01.071+0000] {subprocess.py:93} INFO -     tweets = client.search_recent_tweets(query=query, tweet_fields=['created_at'], max_results=10)
[2025-05-04T00:22:01.072+0000] {subprocess.py:93} INFO -   File "/home/***/.local/lib/python3.9/site-packages/tweepy/client.py", line 1270, in search_recent_tweets
[2025-05-04T00:22:01.073+0000] {subprocess.py:93} INFO -     return self._make_request(
[2025-05-04T00:22:01.074+0000] {subprocess.py:93} INFO -   File "/home/***/.local/lib/python3.9/site-packages/tweepy/client.py", line 129, in _make_request
[2025-05-04T00:22:01.075+0000] {subprocess.py:93} INFO -     response = self.request(method, route, params=request_params,
[2025-05-04T00:22:01.076+0000] {subprocess.py:93} INFO -   File "/home/***/.local/lib/python3.9/site-packages/tweepy/client.py", line 84, in request
[2025-05-04T00:22:01.077+0000] {subprocess.py:93} INFO -     with self.session.request(
[2025-05-04T00:22:01.079+0000] {subprocess.py:93} INFO -   File "/home/***/.local/lib/python3.9/site-packages/requests/sessions.py", line 589, in request
[2025-05-04T00:22:01.080+0000] {subprocess.py:93} INFO -     resp = self.send(prep, **send_kwargs)
[2025-05-04T00:22:01.081+0000] {subprocess.py:93} INFO -   File "/home/***/.local/lib/python3.9/site-packages/requests/sessions.py", line 703, in send
[2025-05-04T00:22:01.082+0000] {subprocess.py:93} INFO -     r = adapter.send(request, **kwargs)
[2025-05-04T00:22:01.083+0000] {subprocess.py:93} INFO -   File "/home/***/.local/lib/python3.9/site-packages/requests/adapters.py", line 700, in send
[2025-05-04T00:22:01.084+0000] {subprocess.py:93} INFO -     raise ConnectionError(e, request=request)
[2025-05-04T00:22:01.085+0000] {subprocess.py:93} INFO - requests.exceptions.ConnectionError: HTTPSConnectionPool(host='api.twitter.com', port=443): Max retries exceeded with url: /2/tweets/search/recent?tweet.fields=created_at&max_results=10&query=Tesla+-is%3Aretweet+lang%3Aen (Caused by NewConnectionError('<urllib3.connection.HTTPSConnection object at 0x7f749b16baf0>: Failed to establish a new connection: [Errno 110] Connection timed out'))
[2025-05-04T00:22:01.154+0000] {subprocess.py:97} INFO - Command exited with return code 1
[2025-05-04T00:22:01.375+0000] {taskinstance.py:3310} ERROR - Task failed with exception
Traceback (most recent call last):
  File "/home/airflow/.local/lib/python3.9/site-packages/airflow/models/taskinstance.py", line 767, in _execute_task
    result = _execute_callable(context=context, **execute_callable_kwargs)
  File "/home/airflow/.local/lib/python3.9/site-packages/airflow/models/taskinstance.py", line 733, in _execute_callable
    return ExecutionCallableRunner(
  File "/home/airflow/.local/lib/python3.9/site-packages/airflow/utils/operator_helpers.py", line 252, in run
    return self.func(*args, **kwargs)
  File "/home/airflow/.local/lib/python3.9/site-packages/airflow/models/baseoperator.py", line 406, in wrapper
    return func(self, *args, **kwargs)
  File "/home/airflow/.local/lib/python3.9/site-packages/airflow/operators/bash.py", line 249, in execute
    raise AirflowException(
airflow.exceptions.AirflowException: Bash command failed. The command returned a non-zero exit code 1.
[2025-05-04T00:22:01.415+0000] {taskinstance.py:1225} INFO - Marking task as FAILED. dag_id=tweet_sentiment_dag, task_id=collect_tweets, run_id=scheduled__2025-05-03T23:00:00+00:00, execution_date=20250503T230000, start_date=20250504T001302, end_date=20250504T002201
[2025-05-04T00:22:01.482+0000] {taskinstance.py:340} INFO - ::group::Post task execution logs
[2025-05-04T00:22:01.486+0000] {standard_task_runner.py:124} ERROR - Failed to execute job 86 for task collect_tweets (Bash command failed. The command returned a non-zero exit code 1.; 1190)
Traceback (most recent call last):
  File "/home/airflow/.local/lib/python3.9/site-packages/airflow/task/task_runner/standard_task_runner.py", line 117, in _start_by_fork
    ret = args.func(args, dag=self.dag)
  File "/home/airflow/.local/lib/python3.9/site-packages/airflow/cli/cli_config.py", line 49, in command
    return func(*args, **kwargs)
  File "/home/airflow/.local/lib/python3.9/site-packages/airflow/utils/cli.py", line 115, in wrapper
    return f(*args, **kwargs)
  File "/home/airflow/.local/lib/python3.9/site-packages/airflow/cli/commands/task_command.py", line 483, in task_run
    task_return_code = _run_task_by_selected_method(args, _dag, ti)
  File "/home/airflow/.local/lib/python3.9/site-packages/airflow/cli/commands/task_command.py", line 256, in _run_task_by_selected_method
    return _run_raw_task(args, ti)
  File "/home/airflow/.local/lib/python3.9/site-packages/airflow/cli/commands/task_command.py", line 341, in _run_raw_task
    return ti._run_raw_task(
  File "/home/airflow/.local/lib/python3.9/site-packages/airflow/utils/session.py", line 97, in wrapper
    return func(*args, session=session, **kwargs)
  File "/home/airflow/.local/lib/python3.9/site-packages/airflow/models/taskinstance.py", line 3004, in _run_raw_task
    return _run_raw_task(
  File "/home/airflow/.local/lib/python3.9/site-packages/airflow/models/taskinstance.py", line 273, in _run_raw_task
    TaskInstance._execute_task_with_callbacks(
  File "/home/airflow/.local/lib/python3.9/site-packages/airflow/models/taskinstance.py", line 3158, in _execute_task_with_callbacks
    result = self._execute_task(context, task_orig)
  File "/home/airflow/.local/lib/python3.9/site-packages/airflow/models/taskinstance.py", line 3182, in _execute_task
    return _execute_task(self, context, task_orig)
  File "/home/airflow/.local/lib/python3.9/site-packages/airflow/models/taskinstance.py", line 767, in _execute_task
    result = _execute_callable(context=context, **execute_callable_kwargs)
  File "/home/airflow/.local/lib/python3.9/site-packages/airflow/models/taskinstance.py", line 733, in _execute_callable
    return ExecutionCallableRunner(
  File "/home/airflow/.local/lib/python3.9/site-packages/airflow/utils/operator_helpers.py", line 252, in run
    return self.func(*args, **kwargs)
  File "/home/airflow/.local/lib/python3.9/site-packages/airflow/models/baseoperator.py", line 406, in wrapper
    return func(self, *args, **kwargs)
  File "/home/airflow/.local/lib/python3.9/site-packages/airflow/operators/bash.py", line 249, in execute
    raise AirflowException(
airflow.exceptions.AirflowException: Bash command failed. The command returned a non-zero exit code 1.
[2025-05-04T00:22:01.541+0000] {local_task_job_runner.py:266} INFO - Task exited with return code 1
[2025-05-04T00:22:01.639+0000] {taskinstance.py:3900} INFO - 0 downstream tasks scheduled from follow-on schedule check
[2025-05-04T00:22:01.647+0000] {local_task_job_runner.py:245} INFO - ::endgroup::
