[2025-05-07T00:37:19.399+0000] {local_task_job_runner.py:123} INFO - ::group::Pre task execution logs
[2025-05-07T00:37:19.433+0000] {taskinstance.py:2612} INFO - Dependencies all met for dep_context=non-requeueable deps ti=<TaskInstance: BuildELT_dbt.dbt_seed manual__2025-05-07T00:37:16.716937+00:00 [queued]>
[2025-05-07T00:37:19.457+0000] {taskinstance.py:2612} INFO - Dependencies all met for dep_context=requeueable deps ti=<TaskInstance: BuildELT_dbt.dbt_seed manual__2025-05-07T00:37:16.716937+00:00 [queued]>
[2025-05-07T00:37:19.459+0000] {taskinstance.py:2865} INFO - Starting attempt 1 of 1
[2025-05-07T00:37:19.492+0000] {taskinstance.py:2888} INFO - Executing <Task(BashOperator): dbt_seed> on 2025-05-07 00:37:16.716937+00:00
[2025-05-07T00:37:19.505+0000] {standard_task_runner.py:72} INFO - Started process 789 to run task
[2025-05-07T00:37:19.515+0000] {standard_task_runner.py:104} INFO - Running: ['***', 'tasks', 'run', 'BuildELT_dbt', 'dbt_seed', 'manual__2025-05-07T00:37:16.716937+00:00', '--job-id', '44', '--raw', '--subdir', 'DAGS_FOLDER/build_elt_with_dbt.py', '--cfg-path', '/tmp/tmp0ececr74']
[2025-05-07T00:37:19.521+0000] {standard_task_runner.py:105} INFO - Job 44: Subtask dbt_seed
[2025-05-07T00:37:19.600+0000] {task_command.py:467} INFO - Running <TaskInstance: BuildELT_dbt.dbt_seed manual__2025-05-07T00:37:16.716937+00:00 [running]> on host 55fd2231a72d
[2025-05-07T00:37:19.784+0000] {taskinstance.py:3131} INFO - Exporting env vars: AIRFLOW_CTX_DAG_OWNER='***' AIRFLOW_CTX_DAG_ID='BuildELT_dbt' AIRFLOW_CTX_TASK_ID='dbt_seed' AIRFLOW_CTX_EXECUTION_DATE='2025-05-07T00:37:16.716937+00:00' AIRFLOW_CTX_TRY_NUMBER='1' AIRFLOW_CTX_DAG_RUN_ID='manual__2025-05-07T00:37:16.716937+00:00'
[2025-05-07T00:37:19.791+0000] {taskinstance.py:731} INFO - ::endgroup::
[2025-05-07T00:37:19.969+0000] {subprocess.py:63} INFO - Tmp dir root location: /tmp
[2025-05-07T00:37:19.980+0000] {subprocess.py:75} INFO - Running command: ['/usr/bin/bash', '-c', '/home/***/.local/bin/dbt run --profiles-dir /opt/***/tesla_project --project-dir /opt/***/tesla_project']
[2025-05-07T00:37:20.040+0000] {subprocess.py:86} INFO - Output:
[2025-05-07T00:37:26.804+0000] {subprocess.py:93} INFO - [0m00:37:26  Running with dbt=1.8.7
[2025-05-07T00:37:31.352+0000] {subprocess.py:93} INFO - [0m00:37:31  Registered adapter: snowflake=1.8.1
[2025-05-07T00:37:32.893+0000] {subprocess.py:93} INFO - [0m00:37:32  [[33mWARNING[0m]: Configuration paths exist in your dbt_project.yml file which do not apply to any resources.
[2025-05-07T00:37:32.893+0000] {subprocess.py:93} INFO - There are 1 unused configuration paths:
[2025-05-07T00:37:32.894+0000] {subprocess.py:93} INFO - - models.tesla_project.example
[2025-05-07T00:37:33.111+0000] {subprocess.py:93} INFO - [0m00:37:33  Found 3 models, 1 snapshot, 1 seed, 1 source, 459 macros
[2025-05-07T00:37:33.114+0000] {subprocess.py:93} INFO - [0m00:37:33
[2025-05-07T00:37:36.890+0000] {subprocess.py:93} INFO - [0m00:37:36  Concurrency: 1 threads (target='dev')
[2025-05-07T00:37:36.892+0000] {subprocess.py:93} INFO - [0m00:37:36
[2025-05-07T00:37:36.908+0000] {subprocess.py:93} INFO - [0m00:37:36  1 of 3 START sql table model analytics.input ................................... [RUN]
[2025-05-07T00:37:40.076+0000] {subprocess.py:93} INFO - [0m00:37:40  1 of 3 OK created sql table model analytics.input .............................. [[32mSUCCESS 1[0m in 3.16s]
[2025-05-07T00:37:40.081+0000] {subprocess.py:93} INFO - [0m00:37:40  2 of 3 START sql table model analytics.sentiment_features_final ................ [RUN]
[2025-05-07T00:37:42.195+0000] {subprocess.py:93} INFO - [0m00:37:42  2 of 3 OK created sql table model analytics.sentiment_features_final ........... [[32mSUCCESS 1[0m in 2.11s]
[2025-05-07T00:37:42.201+0000] {subprocess.py:93} INFO - [0m00:37:42  3 of 3 START sql table model analytics.output .................................. [RUN]
[2025-05-07T00:37:42.914+0000] {subprocess.py:93} INFO - [0m00:37:42  3 of 3 ERROR creating sql table model analytics.output ......................... [[31mERROR[0m in 0.71s]
[2025-05-07T00:37:42.920+0000] {subprocess.py:93} INFO - [0m00:37:42
[2025-05-07T00:37:42.921+0000] {subprocess.py:93} INFO - [0m00:37:42  Finished running 3 table models in 0 hours 0 minutes and 9.80 seconds (9.80s).
[2025-05-07T00:37:42.983+0000] {subprocess.py:93} INFO - [0m00:37:42
[2025-05-07T00:37:42.984+0000] {subprocess.py:93} INFO - [0m00:37:42  [31mCompleted with 1 error and 0 warnings:[0m
[2025-05-07T00:37:42.985+0000] {subprocess.py:93} INFO - [0m00:37:42
[2025-05-07T00:37:42.986+0000] {subprocess.py:93} INFO - [0m00:37:42    Database Error in model output (models/output/output.sql)
[2025-05-07T00:37:42.987+0000] {subprocess.py:93} INFO -   002003 (42S02): SQL compilation error:
[2025-05-07T00:37:42.988+0000] {subprocess.py:93} INFO -   Object 'DEV.ANALYTICS.REGRESSION_METRICS' does not exist or not authorized.
[2025-05-07T00:37:42.988+0000] {subprocess.py:93} INFO -   compiled code at target/run/tesla_project/models/output/output.sql
[2025-05-07T00:37:42.989+0000] {subprocess.py:93} INFO - [0m00:37:42
[2025-05-07T00:37:42.989+0000] {subprocess.py:93} INFO - [0m00:37:42  Done. PASS=2 WARN=0 ERROR=1 SKIP=0 TOTAL=3
[2025-05-07T00:37:44.108+0000] {subprocess.py:97} INFO - Command exited with return code 1
[2025-05-07T00:37:44.156+0000] {taskinstance.py:3310} ERROR - Task failed with exception
Traceback (most recent call last):
  File "/home/airflow/.local/lib/python3.9/site-packages/airflow/models/taskinstance.py", line 767, in _execute_task
    result = _execute_callable(context=context, **execute_callable_kwargs)
  File "/home/airflow/.local/lib/python3.9/site-packages/airflow/models/taskinstance.py", line 733, in _execute_callable
    return ExecutionCallableRunner(
  File "/home/airflow/.local/lib/python3.9/site-packages/airflow/utils/operator_helpers.py", line 252, in run
    return self.func(*args, **kwargs)
  File "/home/airflow/.local/lib/python3.9/site-packages/airflow/models/baseoperator.py", line 406, in wrapper
    return func(self, *args, **kwargs)
  File "/home/airflow/.local/lib/python3.9/site-packages/airflow/operators/bash.py", line 249, in execute
    raise AirflowException(
airflow.exceptions.AirflowException: Bash command failed. The command returned a non-zero exit code 1.
[2025-05-07T00:37:44.177+0000] {taskinstance.py:1225} INFO - Marking task as FAILED. dag_id=BuildELT_dbt, task_id=dbt_seed, run_id=manual__2025-05-07T00:37:16.716937+00:00, execution_date=20250507T003716, start_date=20250507T003719, end_date=20250507T003744
[2025-05-07T00:37:44.221+0000] {taskinstance.py:340} INFO - ::group::Post task execution logs
[2025-05-07T00:37:44.224+0000] {standard_task_runner.py:124} ERROR - Failed to execute job 44 for task dbt_seed (Bash command failed. The command returned a non-zero exit code 1.; 789)
Traceback (most recent call last):
  File "/home/airflow/.local/lib/python3.9/site-packages/airflow/task/task_runner/standard_task_runner.py", line 117, in _start_by_fork
    ret = args.func(args, dag=self.dag)
  File "/home/airflow/.local/lib/python3.9/site-packages/airflow/cli/cli_config.py", line 49, in command
    return func(*args, **kwargs)
  File "/home/airflow/.local/lib/python3.9/site-packages/airflow/utils/cli.py", line 115, in wrapper
    return f(*args, **kwargs)
  File "/home/airflow/.local/lib/python3.9/site-packages/airflow/cli/commands/task_command.py", line 483, in task_run
    task_return_code = _run_task_by_selected_method(args, _dag, ti)
  File "/home/airflow/.local/lib/python3.9/site-packages/airflow/cli/commands/task_command.py", line 256, in _run_task_by_selected_method
    return _run_raw_task(args, ti)
  File "/home/airflow/.local/lib/python3.9/site-packages/airflow/cli/commands/task_command.py", line 341, in _run_raw_task
    return ti._run_raw_task(
  File "/home/airflow/.local/lib/python3.9/site-packages/airflow/utils/session.py", line 97, in wrapper
    return func(*args, session=session, **kwargs)
  File "/home/airflow/.local/lib/python3.9/site-packages/airflow/models/taskinstance.py", line 3004, in _run_raw_task
    return _run_raw_task(
  File "/home/airflow/.local/lib/python3.9/site-packages/airflow/models/taskinstance.py", line 273, in _run_raw_task
    TaskInstance._execute_task_with_callbacks(
  File "/home/airflow/.local/lib/python3.9/site-packages/airflow/models/taskinstance.py", line 3158, in _execute_task_with_callbacks
    result = self._execute_task(context, task_orig)
  File "/home/airflow/.local/lib/python3.9/site-packages/airflow/models/taskinstance.py", line 3182, in _execute_task
    return _execute_task(self, context, task_orig)
  File "/home/airflow/.local/lib/python3.9/site-packages/airflow/models/taskinstance.py", line 767, in _execute_task
    result = _execute_callable(context=context, **execute_callable_kwargs)
  File "/home/airflow/.local/lib/python3.9/site-packages/airflow/models/taskinstance.py", line 733, in _execute_callable
    return ExecutionCallableRunner(
  File "/home/airflow/.local/lib/python3.9/site-packages/airflow/utils/operator_helpers.py", line 252, in run
    return self.func(*args, **kwargs)
  File "/home/airflow/.local/lib/python3.9/site-packages/airflow/models/baseoperator.py", line 406, in wrapper
    return func(self, *args, **kwargs)
  File "/home/airflow/.local/lib/python3.9/site-packages/airflow/operators/bash.py", line 249, in execute
    raise AirflowException(
airflow.exceptions.AirflowException: Bash command failed. The command returned a non-zero exit code 1.
[2025-05-07T00:37:44.275+0000] {local_task_job_runner.py:266} INFO - Task exited with return code 1
[2025-05-07T00:37:44.321+0000] {taskinstance.py:3900} INFO - 0 downstream tasks scheduled from follow-on schedule check
[2025-05-07T00:37:44.325+0000] {local_task_job_runner.py:245} INFO - ::endgroup::
